Workbook

Sheet Cover
B3: FINANCIAL ANALYSIS
B4: Singapore Airlines vs. Cathay Pacific
B5: Executive Excel Workbook — FADM Group Project (Part I)
B7: Singapore Airlines | E7: Cathay Pacific
B11: Prepared by — Group 1, Section 2
B12: • | C12: Aakash Kallepalli (FT272045)
B13: • | C13: Naman (FT272022)
B14: • | C14: Nikhil Aggarwal (FT272013)
B15: • | C15: Suhaila Abdulkareem (FT272014)
B16: • | C16: Sreshta (FT272009)
B18: Scale, Currency & Reporting Disclaimers
B19: — | C19: Tab 4 (Financial Statements) & Tab 5 (Efficiency) are in INR millions for cross-airline comparability — converted at 1 SGD = 74.45 INR and 1 HKD = 12.12 INR.
B20: — | C20: Tab 6 (Segments) & Tab 9 (Stock) retain native currencies: SIA in SGD, Cathay in HKD. Currencies are never mixed within a single calculation.
B21: — | C21: Reporting periods differ: SIA = 31 March year-end (FY2024/25); Cathay = 31 December year-end (FY2025) — an offset of ~9 months.
B22: — | C22: Cross-airline US$ figures (where shown) use indicative rates S$1 ≈ US$0.75 and HK$1 ≈ US$0.128 and indicate scale only.
B23: — | C23: All figures are as stated in the source document; some source tables disclose only 2 years of segment data and a few minor internal inconsistencies are flagged in Tab 11.
B27: Contents
B28: 1 | C28: Cover
B29: 2 | C29: Executive Summary
B30: 3 | C30: Company Overview
B31: 4 | C31: Financial Statements (INR mn)
B32: 5 | C32: Efficiency Metrics
B33: 6 | C33: Segment Analysis
B34: 7 | C34: Acquisitions & Strategy
B35: 8 | C35: Shareholding & Governance
B36: 9 | C36: Stock Market Analysis
B37: 10 | C37: Charts Data
B38: 11 | C38: Assumptions & Notes

Sheet Executive Summary
A1: Executive Summary
A2: Latest reported full year · group level · native currencies as labelled
B4: Headline Group Comparison (latest FY)
B5: Metric (latest FY) | C5: Singapore Airlines | D5: Cathay Group | E5: Comment
B6: Revenue | C6: S$19,539.8m (+2.8%) | D6: HK$116,766m (+11.9%) | E6: Cathay growing faster off a lower base
B7: Operating profit | C7: S$1,709.1m (-37.3%) | D7: HK$14,458m (+3.8%) | E7: SIA margin squeezed by cost inflation
B8: Operating margin | C8: 8.7% | D8: 12.4% | E8: Cathay more profitable operationally
B9: Net profit (attrib.) | C9: S$2,778.0m | D9: HK$10,828m | E9: SIA flattered by S$1,097.9m one-off gain
B10: Total assets | C10: S$43,086.8m | D10: HK$177,051m | E10: —
B11: Total equity | C11: S$16,070.0m | D11: HK$60,117m | E11: SIA more strongly capitalised
B13: Key Takeaways
B14: ▸ | C14: Near-identical portfolio model (premium flag carrier + low-cost arm + cargo + engineering/support); Cathay even more revenue-concentrated in its flag carrier (90.5%) than SIA (85.3%).
B15: ▸ | C15: Flag-carrier segment dominates revenue, assets and profit for both; everything else is comparatively marginal.
B16: ▸ | C16: Cathay had stronger operating momentum (rev +11.9%, op. margin 12.4%) on continued capacity recovery; SIA, already largely recovered, grew at industry pace and saw operating profit fall on cost inflation.
B17: ▸ | C17: Low-cost units are the weak spot for both: Scoot revenue contracted (-4.4%) and HK Express losses widened to HK$996m.
B18: ▸ | C18: Strategic associates define each regional bet: SIA's 25.1% of Air India (post-Vistara merger) vs Cathay's 15.09% of Air China.
B19: ▸ | C19: SIA holds the stronger balance sheet and capital base; Cathay shows the stronger underlying operating recovery.
B21: Investment Verdict
B22: Singapore Airlines | C22: Stability play. Blue-chip, Temasek-backed, low beta (~0.50), annualised volatility 17.86%. But delivered a NEGATIVE total stock return (-1.74%) over the year on Air India loss drag — low volatility did not protect against a fundamental earnings headwind.
B23: Cathay Pacific | C23: Higher-risk / higher-reward. Annualised volatility 29.27%, beta ~0.70. Delivered +27.64% total return, outperforming the HSI by ~13pp on cargo strength, capacity recovery and a buyback. Better suited to active risk-tolerant investors.

Sheet Company Overview
A1: Company Overview
A2: Side-by-side strategic profile
C4: Singapore Airlines (SIA) | D4: Cathay Pacific (Cathay Group)
B5: Headquarters | C5: Singapore | D5: Hong Kong
B6: Year-end | C6: 31 March (FY2024/25) | D6: 31 December (FY2025)
B7: Positioning | C7: World-leading premium full-service group; presence in low-cost via Scoot | D7: Premium international carrier with a strong cargo franchise
B8: Core brands | C8: Singapore Airlines, Scoot | D8: Cathay Pacific, Cathay Cargo, HK Express
B9: Principal subsidiaries | C9: Full-Service Carrier (SIA + SIA Cargo), Scoot (Budget Aviation Holdings), SIA Engineering (77.8%); KrisShop, Kris+, Tradewinds | D9: Cathay Pacific (passenger + Cathay Cargo), HK Express (LCC, 100%), AHK Air Hong Kong (cargo, 100%); catering, ground, Asia Miles
B10: Key associates / JVs | C10: Air India 25.1% (post-Vistara merger); SAESL 38.9%; Eagle Services Asia ~31–38%; CAE Flight Training 50% | D10: Air China 15.09%; Air China Cargo 21.01%
B11: Key markets | C11: Asia-Pacific, Europe, North America, Middle East, Africa; premium intl. travellers | D11: Hong Kong, Mainland China, Southeast Asia, major intl. destinations
B12: Strategic focus | C12: Expansion into India + digital ecosystem & sustainability (SAF) | D12: Mainland China connectivity + cargo; low-cost expansion via HK Express
B13: Reportable segments | C13: FSC · LCC (Scoot) · Engineering (SIAEC) · Others | D13: The Company (CX + cargo) · HK Express · Air Hong Kong · Airline services

Sheet Financial Statements
A1: Financial Statements — 5-Year P&L
A2: All figures in INR millions (SIA @1 SGD=74.45 · Cathay @1 HKD=12.12). Years ascending; FY per each company's year-end.
B4: SINGAPORE AIRLINES (INR millions)
B5: Metric | C5: FY2021 | D5: FY2022 | E5: FY2023 | F5: FY2024 | G5: FY2025
B6: Total Revenue | C6: 284093.76 | D6: 566921.86 | E6: 1323333.9 | F6: 1415495.5 | G6: 1454738.1
B7: Total Expenses | C7: 471149.38 | D7: 612314.03 | E7: 1122907 | F7: 1212433.1 | G7: 1327495.6
B8: Operating Profit/(Loss) | C8: =C6-C7 -> -187055.62 | D8: =D6-D7 -> -45392.17 | E8: =E6-E7 -> 200426.84 | F8: =F6-F7 -> 203062.38 | G8: =G6-G7 -> 127242.49
B9: Profit/(Loss) Before Tax | C9: -369063.54 | D9: -81150.5 | E9: 196309.76 | F9: 226112.1 | G9: 220729.36
B10: Profit/(Loss) for the Year | E10: 165197.11 | F10: 200650.2 | G10: 209368.29
B11: Earnings Per Share (INR) | C11: -76.39 | D11: -12.06 | E11: 26.5 | F11: 47.13 | G11: 66.48
B12: Total Assets | C12: 2797927.8 | D12: 3623556 | E12: 3655584.3 | F12: 3295506.9 | G12: 3207812.3
B13: Employee Count | C13: 25547 | D13: 22214 | E13: 22819 | F13: 25619 | G13: 27821
B14: Operating Profit/(Loss) = Total Revenue − Total Expenses
B16: CATHAY PACIFIC (INR millions)
B17: Metric | C17: FY2021 | D17: FY2022 | E17: FY2023 | F17: FY2024 | G17: FY2025
B18: Total Revenue | C18: 552514.44 | D18: 618556.32 | E18: 1145158.2 | F18: 1264976.5 | G18: 1415203.9
B19: Total Expenses | C19: 557968.44 | D19: 576487.8 | E19: 987610.32 | F19: 1105271.3 | G19: 1244639.2
B20: Operating Profit/(Loss) | C20: =C18-C19 -> -5454 | D20: =D18-D19 -> 42068.52 | E20: =E18-E19 -> 157547.88 | F20: =F18-F19 -> 159705.24 | G20: =G18-G19 -> 170564.76
B21: Profit/(Loss) Before Tax | C21: -73410.84 | D21: -74113.8 | E21: 131598.96 | F21: 135780.36 | G21: 149197.2
B22: Profit/(Loss) for the Year | C22: -66975.12 | D22: -80258.64 | E22: 118654.8 | F22: 119842.56 | G22: 131235.36
B23: Earnings Per Share (INR) | C23: -11.53 | D23: -13.62 | E23: 17.06 | F23: 18.08 | G23: 20.06
B24: Total Assets | C24: 2032887.6 | D24: 1873485.4 | E24: 1834555.9 | F24: 1842215.8 | G24: 1872794.5
B25: Employee Count | C25: 21600 | D25: 21200 | E25: 23800 | F25: 30100 | G25: 33000
B26: Operating Profit/(Loss) = Total Revenue − Total Expenses

Sheet Efficiency Metrics
A1: Efficiency Metrics
A2: Asset & labour productivity · computed live from Tab 4 (INR millions). Sales/Asset = Revenue ÷ Total Assets; Sales/Employee = Revenue ÷ Headcount.
B4: SINGAPORE AIRLINES
B5: Metric | C5: FY2021 | D5: FY2022 | E5: FY2023 | F5: FY2024 | G5: FY2025
B6: Sales / Assets (x) | C6: ='Financial Statements'!C6/'Financial Statements'!C12 -> 0.1015372 | D6: ='Financial Statements'!D6/'Financial Statements'!D12 -> 0.15645456 | E6: ='Financial Statements'!E6/'Financial Statements'!E12 -> 0.36200337 | F6: ='Financial Statements'!F6/'Financial Statements'!F12 -> 0.42952285 | G6: ='Financial Statements'!G6/'Financial Statements'!G12 -> 0.45349852
B7: YoY % change | D7: =(D6-C6)/C6 -> 0.5408595 | E7: =(E6-D6)/D6 -> 1.3137924 | F7: =(F6-E6)/E6 -> 0.18651615 | G7: =(G6-F6)/F6 -> 0.055819314
B8: Sales / Employee (INR mn) | C8: ='Financial Statements'!C6/'Financial Statements'!C13 -> 11.120435 | D8: ='Financial Statements'!D6/'Financial Statements'!D13 -> 25.520926 | E8: ='Financial Statements'!E6/'Financial Statements'!E13 -> 57.992632 | F8: ='Financial Statements'!F6/'Financial Statements'!F13 -> 55.251787 | G8: ='Financial Statements'!G6/'Financial Statements'!G13 -> 52.28921
B9: YoY % change | D9: =(D8-C8)/C8 -> 1.2949575 | E9: =(E8-D8)/D8 -> 1.272356 | F9: =(F8-E8)/E8 -> -0.047261953 | G9: =(G8-F8)/F8 -> -0.053619562
B10: 5-yr total % change (Sales/Assets) | G10: =(G6-C6)/C6 -> 3.4663287
B13: CATHAY PACIFIC
B14: Metric | C14: FY2021 | D14: FY2022 | E14: FY2023 | F14: FY2024 | G14: FY2025
B15: Sales / Assets (x) | C15: ='Financial Statements'!C18/'Financial Statements'!C24 -> 0.27178799 | D15: ='Financial Statements'!D18/'Financial Statements'!D24 -> 0.33016341 | E15: ='Financial Statements'!E18/'Financial Statements'!E24 -> 0.62421548 | F15: ='Financial Statements'!F18/'Financial Statements'!F24 -> 0.68666035 | G15: ='Financial Statements'!G18/'Financial Statements'!G24 -> 0.75566428
B16: YoY % change | D16: =(D15-C15)/C15 -> 0.21478294 | E16: =(E15-D15)/D15 -> 0.89062583 | F16: =(F15-E15)/E15 -> 0.10003737 | G16: =(G15-F15)/F15 -> 0.10049208
B17: Sales / Employee (INR mn) | C17: ='Financial Statements'!C18/'Financial Statements'!C25 -> 25.579372 | D17: ='Financial Statements'!D18/'Financial Statements'!D25 -> 29.177185 | E17: ='Financial Statements'!E18/'Financial Statements'!E25 -> 48.115891 | F17: ='Financial Statements'!F18/'Financial Statements'!F25 -> 42.025798 | G17: ='Financial Statements'!G18/'Financial Statements'!G25 -> 42.884967
B18: YoY % change | D18: =(D17-C17)/C17 -> 0.14065289 | E18: =(E17-D17)/D17 -> 0.64909298 | F18: =(F17-E17)/E17 -> -0.12657134 | G18: =(G17-F17)/F17 -> 0.020443854
B19: 5-yr total % change (Sales/Assets) | G19: =(G15-C15)/C15 -> 1.7803446

Sheet Segment Analysis
A1: Segment Analysis
A2: Native currencies — SIA in S$ million (FY2024/25 vs FY2023/24); Cathay in HK$ million (FY2025 vs FY2024). Currencies not mixed.
B4: SINGAPORE AIRLINES (S$ million)
B5: Segment | C5: Ext. revenue FY24/25 | D5: Ext. revenue FY23/24 | E5: Revenue growth | F5: Segment result FY24/25 | G5: Seg. assets 31-Mar-25
B6: Full-Service Carrier | C6: 16676.9 | D6: 16120.6 | E6: =(C6-D6)/D6 -> 0.034508641 | F6: 1668.9 | G6: 34748.2
B7: Low-Cost Carrier (Scoot) | C7: 2255.9 | D7: 2359.5 | E7: =(C7-D7)/D7 -> -0.043907608 | F7: 35.8 | G7: 5944.3
B8: Engineering (SIAEC) | C8: 521.6 | D8: 449.1 | E8: =(C8-D8)/D8 -> 0.16143398 | F8: 14.6 | G8: 1294
B9: Others | C9: 85.4 | D9: 83.5 | E9: =(C9-D9)/D9 -> 0.022754491 | F9: -18.1 | G9: 588.3
B10: Total of segments | C10: =SUM(C6:C9) -> 19539.8 | D10: =SUM(D6:D9) -> 19012.7 | E10: =(C10-D10)/D10 -> 0.027723574 | F10: =SUM(F6:F9) -> 1701.2 | G10: =SUM(G6:G9) -> 42574.8
B13: CATHAY GROUP (HK$ million)
B14: Segment | C14: Ext. revenue 2025 | D14: Ext. revenue 2024 | E14: Revenue growth | F14: Segment profit/(loss) 2025
B15: The Company (CX + Cargo) | C15: 105631 | D15: 93551 | E15: =(C15-D15)/D15 -> 0.12912743 | F15: 13791
B16: HK Express (LCC) | C16: 6778 | D16: 6325 | E16: =(C16-D16)/D16 -> 0.071620553 | F16: -996
B17: Air Hong Kong (cargo) | C17: 3222 | D17: 3375 | E17: =(C17-D17)/D17 -> -0.045333333 | F17: 954
B18: Airline services | C18: 1135 | D18: 1120 | E18: =(C18-D18)/D18 -> 0.013392857 | F18: 709
B19: Total | C19: =SUM(C15:C18) -> 116766 | D19: =SUM(D15:D18) -> 104371 | E19: =(C19-D19)/D19 -> 0.11875904 | F19: =SUM(F15:F18) -> 14458
B22: Segment Revenue Growth vs IATA 2025 Benchmarks
B23: Segment | C23: Group | D23: Revenue growth | E23: IATA benchmark | F23: Read
B24: FSC (pax+cargo) | C24: SIA | D24: 0.035 | E24: Pax +5.3% | F24: Below industry — near full recovery
B25: Scoot (LCC) | C25: SIA | D25: -0.044 | E25: Pax +5.3% | F25: Underperformed; revenue fell
B26: SIAEC (engineering) | C26: SIA | D26: 0.161 | E26: (MRO upcycle) | F26: Strongest segment of either group
B27: The Company (flag+cargo) | C27: Cathay | D27: 0.129 | E27: Pax +5.3% | F27: Far outpaced industry off lower base
B28: HK Express (LCC) | C28: Cathay | D28: 0.072 | E28: Pax +5.3% | F28: Grew but deeply loss-making
B29: Air Hong Kong (cargo) | C29: Cathay | D29: -0.045 | E29: Cargo +3.4% | F29: Lagged; trade-lane shifts

Sheet Acquisitions & Strategy
A1: Acquisitions, Investments & Financing
A2: Strategic transactions over the last five years, with impact on Sales / Profit / Cash Flow
B4: SINGAPORE AIRLINES — Business Acquisitions
B5: Transaction | C5: Period | D5: Value | E5: Strategic objective | F5: Impact (Sales / Profit / Cash Flow)
B6: Air India–Vistara Merger | C6: 2022–2024 | D6: S$360m | E6: Acquire 25.1% stake in enlarged Air India; strengthen India presence | F6: Sales: no direct lift (equity-accounted). Profit: one-off ~S$1.1bn revaluation gain. Cash flow: no op. impact; S$360m investing, funded internally.
B7: Tiger Airways Privatisation & Scoot Integration | C7: Earlier (benefits continued) | D7: S$497.3m | E7: Consolidate low-cost operations under Scoot | F7: Improved fleet utilisation & cost synergies; reduced overlapping admin/regulatory cost; supported operating cash flow.
B9: SIA — Investments & Financing (summary)
B10: ▸ | C10: Investments: short-term deposits/MM instruments (liquidity); Pelago (travel experiences); Kris+ (digital & loyalty); SAF commitments (ESG & fuel security).
B11: ▸ | C11: Financing: COVID rights issue + Mandatory Convertible Bonds (Temasek-backed) raised liquidity & equity; pandemic borrowing funded operations; MCB redemption FY23–25 reduced dilution & leverage. Preserved investment-grade credit.
B13: CATHAY PACIFIC — Business Acquisitions
B14: Transaction | C14: Period | D14: Value | E14: Strategic objective | F14: Impact (Sales / Profit / Cash Flow)
B15: HK Express Acquisition | C15: 2019 (benefits in period) | D15: HK$4.93bn | E15: Entry into low-cost carrier segment | F15: Sales: expanded LCC presence, higher pax volumes post-reopening. Profit: raised fixed cost early, later aided return to profit. Cash flow: initial outflow/leverage, then synergies.
B16: Cathay Dragon Integration | C16: 2020 | D16: Internal restructuring | E16: Eliminate duplicate operations | F16: Reduced duplication & admin cost; improved route efficiency; one-off restructuring charge but long-term savings.
B18: Cathay — Investments & Financing (summary)
B19: ▸ | C19: Investments: Air China 15.09% (Mainland market access); Air China Cargo 21.01% (cargo connectivity); digital cargo & logistics ventures.
B20: ▸ | C20: Financing: HK$39bn government-backed recapitalisation stabilised liquidity; preference shares eased financing pressure; full redemption of government investment (2024) restored independence; debt reduced to a 5-year low.

Sheet Shareholding & Governance
A1: Shareholding & Governance
A2: Ownership structure, free float, board composition and governance scorecard
B4: Singapore Airlines — Major Shareholders (29 May 2025)
B5: Shareholder | C5: Shares | D5: % of Total | E5: Type
B6: Napier Investments Pte. Ltd. (Temasek sub.) | C6: 930959900 | D6: 0.3133 | E6: Direct
B7: Temasek Holdings (Private) Limited | C7: 657306600 | D7: 0.2212 | E7: Direct
B8: Citibank Nominees Singapore | C8: 213152543 | D8: 0.0717 | E8: Nominee / Inst.
B9: DBS Nominees (Private) Limited | C9: 136527334 | D9: 0.0459 | E9: Nominee / Inst.
B10: Raffles Nominees (Pte.) Limited | C10: 100500547 | D10: 0.0338 | E10: Nominee / CDP
B11: DBSN Services Pte. Ltd. | C11: 81240167 | D11: 0.0273 | E11: Nominee
B12: HSBC (Singapore) Nominees | C12: 72765835 | D12: 0.0245 | E12: Nominee / Inst.
B13: UOB Nominees (Private) Limited | C13: 42169250 | D13: 0.0142 | E13: Nominee
B14: Other nominees & brokers (9–20) | C14: 106296706 | D14: 0.0358 | E14: Various
B15: Temasek Group total (direct + deemed) | C15: 1590155897 | D15: 0.5352 | E15: Controlling shareholder
B16: Public float | C16: 1381076985 | D16: 0.4648 | E16: —
B19: Cathay Pacific — Major Shareholders (31 Dec 2025)
B20: Shareholder | C20: Shares held | D20: % of Votes | E20: Basis
B21: Swire Pacific Limited | C21: 2896753089 | D21: 0.4309 | E21: Direct / Shareholders' Agreement
B22: Air China Limited | C22: 1930516334 | D22: 0.2872 | E22: Attributable / Shareholders' Agr.
B23: Qatar Airways Group | C23: 643076181 | D23: 0.0957 | E23: Beneficial (bought back Feb 2026)
B24: Public Shareholders | C24: 1252510907 | D24: 0.1863 | E24: Free float (Dec 2025)
B25: Total issued | C25: =SUM(C21:C24) -> 6722856511 | D25: 1 | E25: —
B28: Governance Scorecard
B29: Dimension | C29: Singapore Airlines | D29: Cathay Pacific
B30: Controlling structure | C30: Temasek 53.52% (single group) | D30: Swire 43.09% + Air China 28.72% = 71.80%
B31: Free float | C31: 46.29% (May 2025) | D31: 18.63% (Dec 2025); ~22.4% post-buyback
B32: Board size | C32: 10 directors | D32: 17 directors
B33: Independent directors | C33: 8 of 10 (80%) | D33: 4 of 17 (23.5%) — HKEx waiver
B34: Chair / CEO separation | C34: Yes (Seah / Goh) | D34: Yes (Healy / Lam)
B35: Board committees | C35: 6 | D35: 9
B36: Govt. involvement | C36: Direct via Temasek + special share | D36: Indirect via Air China (SOE)
B37: Disclosure regime | C37: SGX-ST — 5% + mandatory Top-20 list | D37: HKEx/SFO — 5% threshold; no Top-20
B38: Dividend (latest FY) | C38: S$0.58 / share | D38: HK$0.84 / share
B39: Governance code | C39: SG Code of CG 2018 — full | D39: HK CG Code — full
B40: Auditor | C40: KPMG LLP | D40: KPMG

Sheet Stock Market Analysis
A1: Stock Market Analysis
A2: Weekly closing prices & returns, May 2025 – May 2026. SIA (SGX: C6L) in SGD · Cathay (HKG: 0293) in HKD. Returns computed from price column.
B4: Weekly Price & Return Series
B5: SIA — Week ending | C5: Close (SGD) | D5: Weekly return | F5: Cathay — Week ending | G5: Close (HKD) | H5: Weekly return
B6: 11 May 2025 | C6: 6.9 | D6: 0.0207 | F6: 01 Jun 2025 | G6: 10.42 | H6: -0.0133
B7: 18 May 2025 | C7: 7.05 | D7: =(C7-C6)/C6 -> 0.02173913 | F7: 08 Jun 2025 | G7: 10.3 | H7: =(G7-G6)/G6 -> -0.011516315
B8: 25 May 2025 | C8: 7.13 | D8: =(C8-C7)/C7 -> 0.011347518 | F8: 15 Jun 2025 | G8: 10.06 | H8: =(G8-G7)/G7 -> -0.023300971
B9: 01 Jun 2025 | C9: 7.09 | D9: =(C9-C8)/C8 -> -0.0056100982 | F9: 22 Jun 2025 | G9: 10.76 | H9: =(G9-G8)/G8 -> 0.069582505
B10: 08 Jun 2025 | C10: 6.94 | D10: =(C10-C9)/C9 -> -0.021156559 | F10: 29 Jun 2025 | G10: 10.78 | H10: =(G10-G9)/G9 -> 0.0018587361
B11: 15 Jun 2025 | C11: 6.79 | D11: =(C11-C10)/C10 -> -0.021613833 | F11: 06 Jul 2025 | G11: 11.8 | H11: =(G11-G10)/G10 -> 0.094619666
B12: 22 Jun 2025 | C12: 6.93 | D12: =(C12-C11)/C11 -> 0.020618557 | F12: 13 Jul 2025 | G12: 11.9 | H12: =(G12-G11)/G11 -> 0.0084745763
B13: 29 Jun 2025 | C13: 7.03 | D13: =(C13-C12)/C12 -> 0.014430014 | F13: 20 Jul 2025 | G13: 11.9 | H13: =(G13-G12)/G12 -> 0
B14: 06 Jul 2025 | C14: 7.25 | D14: =(C14-C13)/C13 -> 0.031294452 | F14: 27 Jul 2025 | G14: 11.8 | H14: =(G14-G13)/G13 -> -0.0084033613
B15: 13 Jul 2025 | C15: 7.44 | D15: =(C15-C14)/C14 -> 0.026206897 | F15: 03 Aug 2025 | G15: 10.42 | H15: =(G15-G14)/G14 -> -0.11694915
B16: 20 Jul 2025 | C16: 7.57 | D16: =(C16-C15)/C15 -> 0.017473118 | F16: 10 Aug 2025 | G16: 10.82 | H16: =(G16-G15)/G15 -> 0.038387716
B17: 27 Jul 2025 | C17: 6.82 | D17: =(C17-C16)/C16 -> -0.099075297 | F17: 17 Aug 2025 | G17: 10.71 | H17: =(G17-G16)/G16 -> -0.010166359
B18: 03 Aug 2025 | C18: 6.53 | D18: =(C18-C17)/C17 -> -0.042521994 | F18: 24 Aug 2025 | G18: 10.71 | H18: =(G18-G17)/G17 -> 0
... B57: 03 May 2026 | C57: 6.31 | D57: =(C57-C56)/C56 -> 0.0031796502 | F57: 24 May 2026 | G57: 13.3 | H57: =(G57-G56)/G56 -> 0.055555556
B58: 10 May 2026 | C58: 6.42 | D58: =(C58-C57)/C57 -> 0.017432647
B59: 17 May 2026 | C59: 6.59 | D59: =(C59-C58)/C58 -> 0.026479751
B60: 24 May 2026 | C60: 6.78 | D60: =(C60-C59)/C59 -> 0.028831563
B63: Price & Volatility Metrics (computed)
B64: Metric | C64: Singapore Airlines (SGD) | D64: Cathay Pacific (HKD)
B65: Starting price | C65: =C6 -> 6.9 | D65: =G6 -> 10.42
B66: Ending price | C66: =C60 -> 6.78 | D66: =G57 -> 13.3
B67: Total return | C67: =(C60-C6)/C6 -> -0.017391304 | D67: =(G57-G6)/G6 -> 0.27639155
B68: 52-week high | C68: =MAX(C6:C60) -> 7.57 | D68: =MAX(G6:G57) -> 14.06
B69: 52-week low | C69: =MIN(C6:C60) -> 6.29 | D69: =MIN(G6:G57) -> 10.06
B70: Avg weekly return | C70: =AVERAGE(D7:D60) -> -8.9447797e-06 | D70: =AVERAGE(H7:H57) -> 0.005632266
B71: Best single week | C71: =MAX(D7:D60) -> 0.05511811 | D71: =MAX(H7:H57) -> 0.10534591
B72: Worst single week | C72: =MIN(D7:D60) -> -0.099075297 | D72: =MIN(H7:H57) -> -0.11694915
B73: Weekly std dev | C73: =STDEVP(D7:D60) -> 0.024840188 | D73: =STDEVP(H7:H57) -> 0.040913589
B74: Annualised volatility (×√52) | C74: =STDEVP(D7:D60)*SQRT(52) -> 0.17912515 | D74: =STDEVP(H7:H57)*SQRT(52) -> 0.29503208
B75: Beta (5Y monthly) | C75: 0.50 (confirmed) | D75: ~0.70 (estimated)
B76: Market index benchmark | C76: STI (~+5%) | D76: HSI (~+15%)
B77: vs. market index | C77: Underperformed (~-6.74pp) | D77: Outperformed (~+12.64pp)
B80: Major Corporate Announcements (May 2025 – May 2026)
B81: Airline | C81: Date | D81: Announcement | H81: Impact
B82: SIA | C82: Jul 2025 | D82: 52-week high SGD 7.57 on strong summer travel demand | H82: Positive
B83: SIA | C83: Nov 2025 | D83: H1 FY2026: net profit -67.8% to SGD 239M; record revenue SGD 9.675B; Air India drag | H83: Negative
...

Sheet Charts Data
A1: Charts Data
B4: 1 · Segment Revenue Mix → Doughnut / Pie (one per airline)
B5: Segment (SIA) | C5: % of revenue | E5: Segment (Cathay) | F5: % of revenue
B6: Full-Service Carrier | C6: 0.853 | E6: The Company (CX + Cargo) | F6: 0.905
B7: Low-Cost Carrier (Scoot) | C7: 0.115 | E7: HK Express | F7: 0.058
B8: Engineering (SIAEC) | C8: 0.027 | E8: Air Hong Kong | F8: 0.028
B9: Others | C9: 0.004 | E9: Airline services | F9: 0.01
B12: 2 · Segment Growth vs IATA → Clustered Column + 2 reference lines
B13: Segment | C13: Revenue growth | D13: IATA pax +5.3% | E13: IATA cargo +3.4%
B14: SIA: FSC | C14: 0.035 | D14: 0.053 | E14: 0.034
B15: SIA: Scoot | C15: -0.044 | D15: 0.053 | E15: 0.034
B16: SIA: SIAEC | C16: 0.161 | D16: 0.053 | E16: 0.034
B17: CX: The Company | C17: 0.129 | D17: 0.053 | E17: 0.034
B18: CX: HK Express | C18: 0.072 | D18: 0.053 | E18: 0.034
B19: CX: Air Hong Kong | C19: -0.045 | D19: 0.053 | E19: 0.034
B22: 3 · Group Scale (US$ bn, indicative) → Clustered Column
B23: Metric (US$ bn) | C23: Singapore Airlines | D23: Cathay Group
B24: Revenue | C24: 14.7 | D24: 14.9
B25: Total assets | C25: 32.3 | D25: 22.7
B26: Total equity | C26: 12.1 | D26: 7.7
B29: 4 · Profitability Margins → Clustered Column
B30: Margin | C30: Singapore Airlines | D30: Cathay Group
B31: Operating margin | C31: 0.087 | D31: 0.124
B32: Net margin* | C32: 0.142 | D32: 0.093

Sheet Assumptions & Notes
A1: Assumptions & Notes
A2: FX rates, methodology, and data caveats
B4: FX Rates Used (source-stated)
B5: Item | C5: Value / Note
B6: SGD → INR | C6: 1 SGD = 74.45 INR (Tabs 4–5)
B7: HKD → INR | C7: 1 HKD = 12.12 INR (Tabs 4–5)
B8: SGD → USD | C8: S$1 ≈ US$0.75 (Tab 10 scale chart, indicative)
B9: HKD → USD | C9: HK$1 ≈ US$0.128 (Tab 10 scale chart, indicative)
B11: Methodology & Caveats
B12: ▸ | C12: Year-end mismatch: SIA reports to 31 March (FY2024/25); Cathay to 31 December (FY2025) — a ~9-month offset. Cross-airline comparisons rely mainly on currency-neutral measures (growth, margins, mix).
B13: ▸ | C13: Segment data: both companies disclose only TWO years of segment revenue/result/assets, so a full 5-year segment trend cannot be reconstructed without estimation; segment growth shown is the latest year-on-year movement.
B14: ▸ | C14: Operating profit on Tab 4 is computed (Revenue − Expenses) and ties to the source within rounding.
B15: ▸ | C15: SIA 'Profit for the Year' is not disclosed for FY2021 and FY2022 in the source; those cells are intentionally blank.
B16: ▸ | C16: Stock 52-week low discrepancy: the SIA event commentary cites SGD 5.90 (Mar 2026) but the supplied weekly table bottoms at SGD 6.29 (26 Apr 2026). Computed metrics use the table; treat 5.90 as an unreconciled source note.
B17: ▸ | C17: Weekly returns are recomputed from the price column; the first week of each series uses the as-reported figure because the prior price predates the window.
B18: ▸ | C18: Colour convention: BLUE text = source input value; BLACK text = formula/calculation; GREEN cross-sheet links where used. Gridlines are switched off on every tab by design.
B19: ▸ | C19: All monetary scales are labelled in headers (INR mn / S$ m / HK$ m / SGD / HKD / US$ bn). Currencies are never mixed inside a single calculation.
B20: ▸ | C20: Volatility uses the population standard deviation (STDEVP) of computed weekly returns × √52, consistent with the source headline figures (SIA 2.48% / 17.86%; Cathay 4.06% / 29.27%); using sample STDEV instead would raise these by ~0.2pp.
B21: ▸ | C21: Source: SIA & Cathay Pacific annual reports and weekly stock data, May 2025 – May 2026, as supplied in the project document (FADM Group 1, Section 2, Part I).

Sheet Part 2
B3: PART 2 — PROFITABILITY, EXPENSE & GROWTH ANALYSIS
B4: Singapore Airlines vs. Cathay Pacific
B5: FADM Group Project — Group 1, Section 2 · Part-2
B7: What this file delivers (per the Part-2 brief)
C8: 1 · Profit ratios over the last five years (to latest available, FY2025) for the company and competitor(s).
C9: 2 · Expense analysis explaining the change in profitability (total-cost ratio and its link to margins).
C10: 3 · Trend in sales, profit and asset growth over five years, compared across companies.
B11: Currency & scale
C12: All absolute figures are in INR millions, converted in Part-1 (1 SGD = 74.45 INR; 1 HKD = 12.12 INR) for cross-airline comparability.
C13: Profit ratios and margins are unit-free, so they are currency-neutral regardless of the conversion. Growth is shown as YoY %, index (FY2021 = 100) and CAGR — all currency-neutral.
B15: Contents
B16: 1 | C16: Profit Ratios
B17: 2 | C17: Extended Ratios (ROE, ROCE, EBIT & EBITDA Margins)
B18: 3 | C18: Expense Analysis
B19: 4 | C19: Notes and Assumptions Part 2
B20: 5 | C20: Growth Trends

Sheet Profit Ratios
B4: SINGAPORE AIRLINES
B5: Metric | C5: FY2021 | D5: FY2022 | E5: FY2023 | F5: FY2024 | G5: FY2025
B6: Operating Profit Margin | C6: -0.65842917 | D6: -0.080067772 | E6: 0.15145599 | F6: 0.14345675 | G6: 0.087467627
B7: PBT Margin | C7: -1.2990906 | D7: -0.1431423 | E7: 0.14834485 | F7: 0.1597406 | G7: 0.15173134
B8: Net Profit Margin | E8: 0.12483404 | F8: 0.14175262 | G8: 0.14392164
B9: Return on Assets (net) | E9: 0.045190343 | F9: 0.06088599 | G9: 0.065268249
B10: Total Expense Ratio (Exp/Rev) | C10: 1.6584292 | D10: 1.0800678 | E10: 0.84854401 | F10: 0.85654325 | G10: 0.91253237
B13: CATHAY PACIFIC
B14: Metric | C14: FY2021 | D14: FY2022 | E14: FY2023 | F14: FY2024 | G14: FY2025
B15: Operating Profit Margin | C15: -0.0098712352 | D15: 0.068010816 | E15: 0.13757739 | F15: 0.12625154 | G15: 0.1205231
B16: PBT Margin | C16: -0.13286683 | D16: -0.11981738 | E16: 0.11491771 | F16: 0.10733825 | G16: 0.10542452
B17: Net Profit Margin | C17: -0.12121877 | D17: -0.12975155 | E17: 0.10361433 | F17: 0.09473896 | G17: 0.092732473
B18: Return on Assets (net) | C18: -0.032945805 | D18: -0.042839214 | E18: 0.064677669 | F18: 0.065053488 | G18: 0.070074618
B19: Total Expense Ratio (Exp/Rev) | C19: 1.0098712 | D19: 0.93198918 | E19: 0.86242261 | F19: 0.87374846 | G19: 0.8794769
B22: Head-to-Head — Latest Year (FY2025)
B23: Ratio | C23: Singapore Airlines | D23: Cathay Pacific | E23: Better
B24: Operating Profit Margin | C24: 0.087467627 | D24: 0.1205231 | E24: Cathay
B25: Net Profit Margin | C25: 0.14392164 | D25: 0.092732473 | E25: SIA
B26: Return on Assets | C26: 0.065268249 | D26: 0.070074618 | E26: Cathay
B27: Total Expense Ratio | C27: 0.91253237 | D27: 0.8794769 | E27: Cathay (lower cost ratio)

Sheet Extended Ratios
B2: Extended Profitability Ratios — ROE, ROCE, EBIT & EBITDA Margins
B4: SINGAPORE AIRLINES
B5: Metric | D5: FY2024 | E5: FY2025
B6: Total Equity (S$ mn) | D6: 16744.6 | E6: 16070
B7: Capital Employed = TA - Curr. Liab. (S$ mn) | D7: 31593 | E7: 29131.7
B8: Depreciation & Amortisation (S$ mn) | D8: 2185.8 | E8: 2381
B9: FX rate used (1 SGD = INR) | D9: 74.45
B10: Total Equity (INR mn) | D10: =D6*$D$9 -> 1246635.5 | E10: =E6*$D$9 -> 1196411.5
B11: Capital Employed (INR mn) | D11: =D7*$D$9 -> 2352098.9 | E11: =E7*$D$9 -> 2168855.1
B12: D&A (INR mn) | D12: =D8*$D$9 -> 162732.81 | E12: =E8*$D$9 -> 177265.45
B14: Ratios (computed)
B15: ROE = Net Profit / Total Equity | D15: ='Profit Ratios'!F8*'Growth Trends'!F6/D10 -> 0.16095339 | E15: ='Profit Ratios'!G8*'Growth Trends'!G6/E10 -> 0.17499689
B16: ROCE = Operating Profit / Capital Employed | D16: ='Profit Ratios'!F6*'Growth Trends'!F6/D11 -> 0.086332418 | E16: ='Profit Ratios'!G6*'Growth Trends'!G6/E11 -> 0.058668047
B17: EBIT Margin (= Operating Profit Margin) | D17: ='Profit Ratios'!F6 -> 0.14345675 | E17: ='Profit Ratios'!G6 -> 0.087467627
B18: EBITDA Margin = (Op. Profit + D&A) / Revenue | D18: =('Profit Ratios'!F6*'Growth Trends'!F6+D12)/'Growth Trends'!F6 -> 0.258422 | E18: =('Profit Ratios'!G6*'Growth Trends'!G6+E12)/'Growth Trends'!G6 -> 0.20932148
B21: CATHAY PACIFIC
B22: Metric | D22: FY2024 | E22: FY2025
B23: Total Equity (HK$ mn) | D23: 52507 | E23: 60117
B24: Capital Employed = TA - Curr. Liab. (HK$ mn) | D24: 121005 | E24: 118008
B25: Depreciation & Amortisation (HK$ mn) | D25: 12065 | E25: 11570
B26: FX rate used (1 HKD = INR) | D26: 12.12
B27: Total Equity (INR mn) | D27: =D23*$D$26 -> 636384.84 | E27: =E23*$D$26 -> 728618.04
B28: Capital Employed (INR mn) | D28: =D24*$D$26 -> 1466580.6 | E28: =E24*$D$26 -> 1430257
B29: D&A (INR mn) | D29: =D25*$D$26 -> 146227.8 | E29: =E25*$D$26 -> 140228.4
B31: Ratios (computed)
B32: ROE = Net Profit / Total Equity | D32: ='Profit Ratios'!F17*'Growth Trends'!F19/D27 -> 0.18831775 | E32: ='Profit Ratios'!G17*'Growth Trends'!G19/E27 -> 0.18011544
B33: ROCE = Operating Profit / Capital Employed | D33: ='Profit Ratios'!F15*'Growth Trends'!F19/D28 -> 0.10889633 | E33: ='Profit Ratios'!G15*'Growth Trends'!G19/E28 -> 0.11925463
B34: EBIT Margin (= Operating Profit Margin) | D34: ='Profit Ratios'!F15 -> 0.12625154 | E34: ='Profit Ratios'!G15 -> 0.1205231
B35: EBITDA Margin = (Op. Profit + D&A) / Revenue | D35: =('Profit Ratios'!F15*'Growth Trends'!F19+D29)/'Growth Trends'!F19 -> 0.24184879 | E35: =('Profit Ratios'!G15*'Growth Trends'!G19+E29)/'Growth Trends'!G19 -> 0.21961016
B38: Head-to-Head — Latest Year (FY2025)
B39: Ratio | C39: Singapore Airlines | D39: Cathay Pacific | E39: Better
B40: ROE (Return on Equity) | C40: =E15 -> 0.17499689 | D40: =E32 -> 0.18011544 | E40: =IF(C40>D40,"SIA","Cathay") -> Cathay
B41: ROCE (Return on Capital Employed) | C41: =E16 -> 0.058668047 | D41: =E33 -> 0.11925463 | E41: =IF(C41>D41,"SIA","Cathay") -> Cathay
B42: EBIT Margin | C42: =E17 -> 0.087467627 | D42: =E34 -> 0.1205231 | E42: =IF(C42>D42,"SIA","Cathay") -> Cathay
B43: EBITDA Margin | C43: =E18 -> 0.20932148 | D43: =E35 -> 0.21961016 | E43: =IF(C43>D43,"SIA","Cathay") -> Cathay

Sheet Expense Analysis
A1: Expense Analysis — Explaining the Change in Profitability
A2: Total Expense Ratio = Total Expenses ÷ Revenue. A falling ratio lifts margins; a rising ratio compresses them.
B4: SINGAPORE AIRLINES
B5: Metric | C5: FY2021 | D5: FY2022 | E5: FY2023 | F5: FY2024 | G5: FY2025
B6: Total Expense Ratio | C6: 1.6584292 | D6: 1.0800678 | E6: 0.84854401 | F6: 0.85654325 | G6: 0.91253237
B7: YoY change (pp) | D7: -57.83614 | E7: -23.152376 | F7: 0.7999245 | G7: 5.5989118
B8: Operating Margin (= 1 − ratio) | C8: -0.65842917 | D8: -0.080067772 | E8: 0.15145599 | F8: 0.14345675 | G8: 0.087467627
B10: CATHAY PACIFIC
B11: Metric | C11: FY2021 | D11: FY2022 | E11: FY2023 | F11: FY2024 | G11: FY2025
B12: Total Expense Ratio | C12: 1.0098712 | D12: 0.93198918 | E12: 0.86242261 | F12: 0.87374846 | G12: 0.8794769
B13: YoY change (pp) | D13: -7.7882051 | E13: -6.9566577 | F13: 1.1325848 | G13: 0.57284475
B14: Operating Margin (= 1 − ratio) | C14: -0.0098712352 | D14: 0.068010816 | E14: 0.13757739 | F14: 0.12625154 | G14: 0.1205231
B16: What the expense ratio tells us
B17: ▸ | C17: Recovery phase (FY2021→FY2023): both airlines' expense ratios collapsed as revenue rebounded faster than costs — SIA from ~166% to ~85%, Cathay from ~101% to ~86% — turning deep operating losses into healthy profits. This is the single biggest driver of the profitability swing.
B18: ▸ | C18: Compression phase (FY2024→FY2025): SIA's expense ratio crept back up (≈85.7% → 91.3%), cutting operating margin from ~14.3% to ~8.7%. Per the Part-1 commentary this reflects higher staff and fuel costs and softer passenger yields — i.e. costs rising faster than revenue near full recovery.
B19: ▸ | C19: Cathay held a lower expense ratio in FY2025 (≈87.9% vs SIA's 91.3%), so it converted revenue to operating profit more efficiently in the latest year despite a smaller absolute revenue base.
B20: ▸ | C20: Bottom line: the change in profitability for both carriers is overwhelmingly a cost-ratio story — margin moves track the expense ratio almost one-for-one (Operating Margin = 1 − Expense Ratio).

Sheet Growth Trends
A1: Growth Trends — Sales, Profit & Assets (5 Years)
A2: INR millions. YoY %, Index (FY2021 = 100) and 5-yr CAGR. Profit growth is 'n.m.' across the loss-to-profit transition.
B4: SINGAPORE AIRLINES
B5: Measure | C5: FY2021 | D5: FY2022 | E5: FY2023 | F5: FY2024 | G5: FY2025 | H5: 5-yr CAGR
B6: REVENUE (INR mn) | C6: 284093.76 | D6: 566921.86 | E6: 1323333.9 | F6: 1415495.5 | G6: 1454738.1 | H6: 0.50428727
B7: YoY growth | D7: 0.99554492 | E7: 1.3342438 | F7: 0.069643544 | G7: 0.027723571
B8: Index (FY21=100) | C8: 100 | D8: 199.55449 | E8: 465.80884 | F8: 498.24942 | G8: 512.06268
B9: OPERATING PROFIT (INR mn) | C9: -187055.62 | D9: -45392.17 | E9: 200426.84 | F9: 203062.38 | G9: 127242.49 | H9: n.m.
B10: YoY growth | D10: n.m. | E10: n.m. | F10: 0.013149636 | G10: -0.37338226
B11: NET PROFIT (INR mn) | E11: 165197.11 | F11: 200650.2 | G11: 209368.29 | H11: n.m.
B12: YoY growth | D12: n.m. | E12: n.m. | F12: 0.21461084 | G12: 0.043449197
B13: TOTAL ASSETS (INR mn) | C13: 2797927.8 | D13: 3623556 | E13: 3655584.3 | F13: 3295506.9 | G13: 3207812.3 | H13: 0.034768287
B14: YoY growth | D14: 0.29508559 | E14: 0.008838939 | F14: -0.098500646 | G14: -0.02661037
B15: Index (FY21=100) | C15: 100 | D15: 129.50856 | E15: 130.65328 | F15: 117.78384 | G15: 114.64957
B17: CATHAY PACIFIC
B18: Measure | C18: FY2021 | D18: FY2022 | E18: FY2023 | F18: FY2024 | G18: FY2025 | H18: 5-yr CAGR
B19: REVENUE (INR mn) | C19: 552514.44 | D19: 618556.32 | E19: 1145158.2 | F19: 1264976.5 | G19: 1415203.9 | H19: 0.2650825
B20: YoY growth | D20: 0.11952969 | E20: 0.85134023 | F20: 0.10463036 | G20: 0.11875904
B21: Index (FY21=100) | C21: 100 | D21: 111.95297 | E21: 207.26304 | F21: 228.94904 | G21: 256.13881
B22: OPERATING PROFIT (INR mn) | C22: -5454 | D22: 42068.52 | E22: 157547.88 | F22: 159705.24 | G22: 170564.76 | H22: n.m.
B23: YoY growth | D23: n.m. | E23: 2.7450303 | F23: 0.013693361 | G23: 0.067997268
B24: NET PROFIT (INR mn) | C24: -66975.12 | D24: -80258.64 | E24: 118654.8 | F24: 119842.56 | G24: 131235.36 | H24: n.m.
B25: YoY growth | D25: n.m. | E25: n.m. | F25: 0.010010215 | G25: 0.095064725
B26: TOTAL ASSETS (INR mn) | C26: 2032887.6 | D26: 1873485.4 | E26: 1834555.9 | F26: 1842215.8 | G26: 1872794.5 | H26: -0.02029756
B27: YoY growth | D27: -0.078411742 | E27: -0.020779154 | F27: 0.0041753102 | G27: 0.016598903
B28: Index (FY21=100) | C28: 100 | D28: 92.158826 | E28: 90.243843 | F28: 90.620639 | G28: 92.124843
B30: Reading the trends
B31: ▸ | C31: Sales: both recovered strongly off COVID lows. SIA revenue grew at a ~50% CAGR FY2021→FY2025 (a low base distorts this) but has now plateaued (+2.8% in the latest year). Cathay's revenue CAGR (~27%) is lower because it started from a higher base, yet it grew +11.9% in the latest year — still in catch-up mode.
B32: ▸ | C32: Profit: both swung from heavy losses (FY2021–22) to solid profits (FY2023 onward); growth rates across the sign change are not meaningful, so the absolute trajectory is the honest read.
B33: ▸ | C33: Assets: SIA's asset base shrank modestly (≈ −3% CAGR) as pandemic-era liquidity unwound, while Cathay's was broadly flat (≈ −2% CAGR) — neither airline is asset-expanding, so revenue growth is being driven by better utilisation rather than a bigger balance sheet.

Sheet Notes and assumptions Part 2
A1: Notes & Assumptions
A2: FX, methodology, scope and data limitations
B4: FX rates used (source-stated)
B5: Item | C5: Value / note
B6: SGD → INR | C6: 1 SGD = 74.45 INR
B7: HKD → INR | C7: 1 HKD = 12.12 INR
B8: Ratios | C8: Margins/ROA are unit-free → currency-neutral
B9: Growth | C9: YoY %, Index (FY21=100) and CAGR → currency-neutral
B11: Methodology, scope & limitations
B12: ▸ | C12: SCOPE: the brief requires the company + two competitors (three entities). Only two airlines (SIA, Cathay) have data in the supplied material. No third airline's figures were invented; use the 'Competitor 3 (Template)' tab to add one.
B13: ▸ | C13: Period: 'last five years ending 31.03.2023 or latest available'. This file uses the latest available five years per company (FY2021–FY2025).
B14: ▸ | C14: Year-end mismatch: SIA reports to 31 March; Cathay to 31 December — a ~9-month offset. Cross-airline comparisons rely on ratios and growth, which are basis-robust.
B15: ▸ | C15: Operating Profit = Revenue − Expenses (computed); ties to the Part-1 figures within rounding.
B16: ▸ | C16: SIA net profit is not disclosed for FY2021–FY2022 in the source, so net margin / ROA / net-profit growth are blank or 'n.m.' for those years.
B17: ▸ | C17: Expense analysis is at the total-cost-ratio level only — the source gives aggregate Total Expenses, not a fuel/staff/maintenance/depreciation breakdown. A line-item decomposition needs each airline's detailed P&L notes.
B18: ▸ | C18: Profit growth across the FY2021–22 loss years is marked 'n.m.' because percentage growth from a negative base is misleading; the absolute profit trajectory is the reliable read.
B19: ▸ | C19: Latest-year operating margins computed here (SIA ~8.7%, Cathay ~12.1%) use the INR-converted statutory P&L; Part-1's group-summary page quoted Cathay ~12.4% on a slightly different basis — a minor, expected difference.
B20: ▸ | C20: Colour key: yellow = input cell to fill; blue text = source input; black = formula. Gridlines off on every tab by design.
B21: ▸ | C21: Source: SIA & Cathay Pacific annual reports as supplied in the Part-1 project document (FADM Group 1, Section 2).

Sheet Cover_Part 3
A2: Cash Flow Statement Analysis — Singapore Airlines vs. Cathay Pacific
A3: FADM Group Project · Part III · FY2023 – FY2025
A4: Prepared by — Group 1, Section 2
A6: Scale & Currency: SIA in SGD millions (native) · Cathay in HKD millions (native)
A7: INR conversion: SIA @ 1 SGD = ₹74.45 · Cathay @ 1 HKD = ₹12.12
A8: Reporting period: SIA: FY ending 31 March · Cathay: FY ending 31 December
A9: SIA FY2023 data: FY2023/24 and FY2024/25 sourced from SIA Audited FS FY24/25; FY2022/23 from prior year disclosures
A10: Cathay FY2023 data: FY2024 and FY2025 sourced from Cathay 2025 Annual Report; FY2023 from prior disclosures
A11: CFS methodology: Indirect method for CFO; matching E1 reference format from CFS Case Set 1 2025

Sheet SIA_CFS
A1: Singapore Airlines Group — Consolidated Statement of Cash Flows
A2: All figures in SGD millions (native currency) · Source: SIA Annual Reports
A4: Particulars | B4: FY2022-23 | C4: FY2023-24 | D4: FY2024-25
A5: A. CASH FLOW FROM OPERATING ACTIVITIES
A6: Profit before taxation | B6: 2032 | C6: 3037.1 | D6: 2964.8
A7: Adjustments for non-cash items:
A8: Add: Depreciation | B8: 1895 | C8: 2109.6 | D8: 2308.2
A9: Add: Amortisation of intangible assets | B9: 88 | C9: 76.2 | D9: 72.8
A10: Add: Finance charges | B10: 568 | C10: 424.5 | D10: 395.5
A11: Less: Interest income | B11: -198 | C11: -631.7 | D11: -492
A12: Add/(Less): Other non-cash adjustments (net) | B12: -125 | C12: -943.6 | D12: -1755.5
A13: Operating cash flow before working capital changes | B13: =B6+B7+B8+B9+B10+B11 -> 4385 | C13: =C6+C7+C8+C9+C10+C11 -> 5015.7 | D13: =D6+D7+D8+D9+D10+D11 -> 5249.3
A14: Changes in working capital:
A15: Increase/(Decrease) in trade and other creditors | B15: 280 | C15: 117.8 | D15: 70.2
A16: Increase/(Decrease) in sales in advance of carriage | B16: 420 | C16: 81.8 | D16: -180
A17: Increase/(Decrease) in deferred revenue | B17: 110 | C17: 161.7 | D17: 232.6
A18: (Increase)/Decrease in trade debtors | B18: -185 | C18: -177.7 | D18: 168.8
A19: (Increase)/Decrease in other working capital items (net) | B19: 95 | C19: -126.6 | D19: 57.2
A20: Cash generated from operations | B20: =B12+B14+B15+B16+B17+B18 -> 500 | C20: =C12+C14+C15+C16+C17+C18 -> -760 | D20: =D12+D14+D15+D16+D17+D18 -> -1463.9
A21: Less: Income taxes paid | B21: -10.7 | C21: -10.7 | D21: -11.3
A22: Less: Competition-related settlements paid | B22: 0 | C22: -25.4 | D22: 0
A23: NET CASH FROM OPERATING ACTIVITIES (A) | B23: 4234 | C23: 5042.1 | D23: 4707.7
A25: B. CASH FLOW FROM INVESTING ACTIVITIES
A26: Capital expenditure (PPE purchases) | B26: -1512 | C26: -1231.3 | D26: -1768
A27: Purchase of intangible assets | B27: -82 | C27: -96 | D27: -105.7
A28: Proceeds from disposal of aircraft/PPE | B28: 124 | C28: 96.4 | D28: 0.9
A29: Investments in associated companies | B29: -360 | C29: -3 | D29: -1006.8
A30: Net placement of fixed deposits (>12 months) | B30: -580 | C30: -805.2 | D30: -973.2
A31: Interest received from investments & deposits | B31: 120 | C31: 617 | D31: 480.8
A32: Net purchase/disposal of short-term investments | B32: -45 | C32: -112.2 | D32: -2.7
A33: Dividends received | B33: 30 | C33: 44.1 | D33: 50
A34: Other investing cash flows (net) | B34: 15 | C34: 53.9 | D34: 23
A35: NET CASH USED IN INVESTING ACTIVITIES (B) | B35: -2290 | C35: -1436.2 | D35: -3301.7
A37: C. CASH FLOW FROM FINANCING ACTIVITIES
A38: Dividends paid (shareholders) | B38: -596 | C38: -1130.2 | D38: -1428.8
A39: Dividends paid to non-controlling interests | B39: -16 | C39: -20.7 | D39: -21.4
A40: Interest paid | B40: -391 | C40: -285.3 | D40: -264.5
A41: Proceeds from borrowings | B41: 820 | C41: 417.8 | D41: 901.7
A42: Repayment of borrowings | B42: -1350 | C42: -1267.1 | D42: -736.4
A43: Repayment of lease liabilities | B43: -790 | C43: -739.4 | D43: -697.4
...

Sheet Cathay_CFS
A1: Cathay Pacific Group — Consolidated Statement of Cash Flows
A2: All figures in HKD millions (native currency) · Source: Cathay Pacific Annual Reports
A4: Particulars | B4: FY2023 | C4: FY2024 | D4: FY2025
A5: A. CASH FLOW FROM OPERATING ACTIVITIES
A6: Operating profit | B6: 13024 | C6: 13928 | D6: 14458
A7: Adjustments for non-cash items:
A8: Add: Depreciation of PPE (owned) | B8: 8250 | C8: 7676 | D8: 7658
A9: Add: Depreciation of right-of-use assets | B9: 4200 | C9: 3787 | D9: 3253
A10: Add: Amortisation of intangible assets | B10: 540 | C10: 596 | D10: 659
A11: Add/(Less): Other non-cash adjustments (net) | B11: -745 | C11: -1302 | D11: -753
A12: Operating cash flow before working capital changes | B12: =B6+B8+B9+B10+B11 -> 25269 | C12: =C6+C8+C9+C10+C11 -> 24685 | D12: =D6+D8+D9+D10+D11 -> 25275
A13: Changes in working capital:
A14: (Increase)/Decrease in stock (inventories) | B14: -180 | C14: -419 | D14: -478
A15: (Increase) in trade debtors & other receivables | B15: -850 | C15: -974 | D15: -1345
A16: Increase in trade creditors, other payables | B16: 3200 | C16: 1803 | D16: 2907
A17: Increase in contract liabilities | B17: 1950 | C17: 3087 | D17: 3233
A18: Other working capital changes (net) | B18: -380 | C18: 75 | D18: -247
A19: Cash generated from operations | B19: =B12+B14+B15+B16+B17+B18 -> 29009 | C19: =C12+C14+C15+C16+C17+C18 -> 28257 | D19: =D12+D14+D15+D16+D17+D18 -> 29345
A20: Add: Interest received | B20: 620 | C20: 540 | D20: 346
A21: Less: Interest paid | B21: -3600 | C21: -3246 | D21: -2661
A22: Less: Tax paid | B22: -800 | C22: -2010 | D22: -1449
A23: NET CASH FROM OPERATING ACTIVITIES (A) | B23: 17800 | C23: 23541 | D23: 25381
A25: B. CASH FLOW FROM INVESTING ACTIVITIES
A26: Payments for PPE and intangible assets (Capex) | B26: -8900 | C26: -9207 | D26: -9830
A27: Proceeds from sale of PPE | B27: 380 | C27: 190 | D27: 389
A28: Net decrease/(increase) in liquid funds | B28: -1800 | C28: 2848 | D28: 1451
A29: Net decrease/(increase) in other LT receivables | B29: 280 | C29: 164 | D29: 153
A30: Dividends received from associates | B30: 110 | C30: 93 | D30: 376
A31: Repayment from/(Loan to) associates | B31: 50 | C31: -170 | D31: 17
A32: NET CASH USED IN INVESTING ACTIVITIES (B) | B32: -9880 | C32: -6082 | D32: -7444
A34: C. CASH FLOW FROM FINANCING ACTIVITIES
A35: New financing raised | B35: 18500 | C35: 13112 | D35: 8722
A36: Loan repayments & lease payments (principal) | B36: -14800 | C36: -11812 | D36: -19683
A37: Convertible bonds & warrants repurchase | B37: 0 | C37: -7029 | D37: 0
A38: Preference shares redemption | B38: 0 | C38: -9750 | D38: 0
A39: Dividends paid — ordinary shares | B39: -2768 | C39: -4056 | D39: -4491
A40: Dividends paid — preference shares | B40: -471 | C40: -471 | D40: 0
A41: Other (initial lease benefit etc.) | B41: 0 | C41: 172 | D41: 0
A42: NET CASH USED IN FINANCING ACTIVITIES (C) | B42: 461 | C42: -19834 | D42: -15452
A44: SUMMARY
...

Sheet Comparison_INR
A1: Side-by-Side Cash Flow Comparison — SIA vs. Cathay Pacific (INR millions for comparability)
A2: Conversion: SIA @ 1 SGD = ₹74.45 · Cathay @ 1 HKD = ₹12.12
B3: Singapore Airlines (INR mn) | E3: Cathay Pacific (INR mn)
A4: Metric | B4: FY2022-23 | C4: FY2023-24 | D4: FY2024-25 | E4: FY2023 | F4: FY2024 | G4: FY2025
A5: Net CFO | B5: 315221 | C5: 375384 | D5: 350488 | E5: 215736 | F5: 285317 | G5: 307618
A6: Net CFI | B6: -170490 | C6: -106925 | D6: -245812 | E6: -119746 | F6: -73714 | G6: -90221
A7: Net CFF | B7: -410592 | C7: -653604 | D7: -322108 | E7: 5587 | F7: -240388 | G7: -187278
A8: Net Change in Cash | B8: -116961 | C8: -385145 | D8: -217431 | E8: 101578 | F8: -28785 | G8: 30118
A9: Closing Cash | B9: 424588 | C9: 838009 | D9: 614741 | E9: 101578 | F9: 65981 | G9: 96839
A10: Capital Expenditure | B10: -112568 | C10: -91670 | D10: -131628 | E10: -107868 | F10: -111589 | G10: -119140
A11: Dividends Paid | B11: -44372 | C11: -84143 | D11: -106374 | E11: -33548 | F11: -49159 | G11: -54431
A13: CFO to Capex Ratio (CFO / |Capex|)
A14: SIA CFO / Capex | B14: 2.8 | C14: 4.09 | D14: 2.66
A15: Cathay CFO / Capex | E15: 1.8 | F15: 2.56 | G15: 2.58
A17: Note: FY2023 Cathay data estimated from prior year disclosures. SIA FY2023 uses prior year annual report data.
A19: CASH FLOW RATIO COMPARISON — SIA vs. CATHAY PACIFIC
A20: Ratio | B20: SIA FY23 | C20: SIA FY24 | D20: SIA FY25 | E20: CX FY23 | F20: CX FY24 | G20: CX FY25
A21: Cash Realisation Ratio (×) = CFO / EBIT [>1× desirable; ↑ = better earnings quality] | B21: 1.6284615 | C21: 1.4565808 | D21: 1.4009761 | E21: 1.0707411 | F21: 1.3707348 | G21: 1.4826216
A22: Debt Service Coverage Ratio (×) = CFO / (Interest + Loans + Leases) [>1.5× comfortable; >2× strong] | B22: 1.6728566 | C22: 2.2000611 | D22: 2.7720073 | E22: 0.9673913 | F22: 1.563355 | G22: 1.1359202
A23: Creditworthiness Ratio (×) = (CFO + Interest) / Interest [Higher = stronger credit quality] | B23: 11.828645 | C23: 18.672976 | D23: 18.798488 | E23: 5.9444444 | F23: 8.2523105 | G23: 10.538144
A24: Cash Generation Ratio (×) = CFO / EBITDA [Closer to 1× = better cash conversion] | B24: 0.92384901 | C24: 0.89281793 | D24: 0.81997109 | E24: 0.60106706 | F24: 0.80528854 | G24: 0.88469448
A25: Reinvestment Ratio (×) = Capex / CFO [<1× self-funded; lower = more efficient] | B25: 0.35710912 | C25: 0.2442038 | D25: 0.37555494 | E25: 0.5 | F25: 0.39110488 | G25: 0.38729758
A27: Teal cell = better performer in that year | Ratios are dimensionless — directly comparable across currencies | SIA native SGD; Cathay native HKD
A29: KEY FINDINGS FROM RATIO COMPARISON
A30: Cash Realisation Ratio | B30: SIA leads consistently (1.63→1.40×) vs Cathay (1.07→1.48×). Both >1× confirms accounting profits are backed by real cash. Cathay's steeper rising trend signals improving earnings quality as operations normalised post-COVID.
A31: Debt Service Coverage Ratio | B31: SIA is significantly stronger (1.67→2.77×) vs Cathay (0.97→1.56×). SIA's DSCR of 2.77× in FY25 is exceptional — debt burden substantially reduced after MCB redemptions. Cathay's sub-1× in FY23 reflected the COVID restructuring year; FY24-25 recovery is encouraging.
A32: Creditworthiness Ratio | B32: SIA dominates (11.8→18.8×) vs Cathay (5.9→10.5×). Both show steep improvement as CFO surged and interest costs fell. SIA's ratio is nearly double Cathay's — reflecting its near-complete debt cleanup by FY25. Both are investment-grade quality.
A33: Cash Generation Ratio | B33: SIA (0.82–0.92×) consistently outperforms Cathay (0.60–0.89×), though the gap is narrowing rapidly. Cathay's large D&A base from its massive fleet (owned + ROU) and higher interest/tax outflows suppress its CGR vs EBITDA. Normal for capital-intensive airlines.
A34: Reinvestment Ratio | B34: Cathay (0.39–0.50×) reinvests a consistently higher proportion of CFO into capex — reflecting its more aggressive fleet expansion. SIA's FY25 spike to 0.38× includes the ₹1,007mn Air India stake; core capex ratio is closer to 0.26×, confirming greater operating cash surplus.
A36: ADDITIONAL CASH FLOW RATIOS — COMPARISON (Set 2) SIA vs. Cathay Pacific
A37: Ratio | B37: SIA FY23 | C37: SIA FY24 | D37: SIA FY25 | E37: CX FY23 | F37: CX FY24 | G37: CX FY25
A38: Cash Generation Ratio (×) = CFO / Revenue [Higher = more cash per ₹ of revenue] | B38: 0.23819972 | C38: 0.26506676 | D38: 0.24071688 | E38: 0.1655814 | F38: 0.1965025 | G38: 0.19828906
A39: Asset Efficiency Ratio (×) = CFO / Total Assets [Higher = better asset utilisation] | B39: 0.11893258 | C39: 0.13130469 | D39: 0.11623951 | E39: 0.092708333 | F39: 0.1165396 | G39: 0.1186028
A40: Capital Asset Ratio (×) = CFO / Capex [Higher = better internal funding of capex] | B40: 2.8002646 | C40: 4.0949403 | D40: 2.6627262 | E40: 2 | F40: 2.5568589 | G40: 2.5819939
A41: Cash Flow Adequacy Ratio (×) = CFO / (Capex + Debt Repayments + Dividends) [>1× = fully self-sufficient; <1× = funding gap] | B41: 0.99296435 | C41: 1.1488824 | D41: 1.0119733 | E41: 0.66075207 | F41: 0.92151413 | G41: 0.74641219
A42: External Financing Ratio (×) = New Borrowings / CFO [Lower = less reliance on external debt] | B42: 0.19367029 | C42: 0.082862299 | D42: 0.19153727 | E42: 1.0393258 | F42: 0.55698568 | G42: 0.34364288
A44: Teal = better performer in that year | Ratios dimensionless — comparable across currencies | SIA native SGD; Cathay native HKD
A46: KEY FINDINGS — SET 2 RATIOS
A47: Cash Generation Ratio (CFO / Revenue) | B47: SIA (23.8–26.5%) generates significantly more cash per dollar of revenue than Cathay (16.6–19.8%). Both show steady improvement but SIA's leaner cost base converts revenue to cash more efficiently. Gap narrowing as Cathay's CFO grows faster than revenue.
A48: Asset Efficiency Ratio (CFO / Total Assets) | B48: SIA (11.6–13.1%) modestly outperforms Cathay (9.3–11.9%) in cash generation per unit of assets. Cathay's large fleet asset base (owned + ROU) suppresses its ratio. Both show FY25 improvement, confirming better asset utilisation as capacity fills.
...

Sheet Analysis_Commentary
A1: Cash Flow Analysis — Managerial Commentary
A3: 1. OPERATING CASH FLOW (CFO)
A4: SIA — Trend | B4: SIA's CFO remained strong across all three years: SGD ~4,234mn (FY23) → SGD 5,042mn (FY24) → SGD 4,708mn (FY25). The spike in FY24 was driven by a large increase in advance ticket sales and deferred revenue as post-COVID capacity expansion filled forward bookings. FY25 shows a modest ~7% decline from FY24 peak, partly from a SGD 180mn reversal in sales-in-advance as forward booking normalised and a dip in operating profit margins from rising costs.
A5: Cathay — Trend | B5: Cathay's CFO recovered strongly from a suppressed FY23 base (HKD ~17,800mn) to HKD 23,541mn in FY24 and HKD 25,381mn in FY25 — a 43% cumulative improvement. The acceleration reflects Hong Kong's later-than-SIA capacity recovery post-COVID, surging passenger demand, strong cargo performance, and growing contract liabilities (unearned revenue). Cathay's CFO now comfortably exceeds SIA's on a like-for-like conversion basis.
A6: Comparison | B6: In INR terms, Cathay's CFO (INR ~307,600mn in FY25) is significantly larger than SIA's (INR ~350,389mn in FY25 at 74.45 conversion). Both companies generate healthy operating cash flows well in excess of their annual capex, indicating sound business fundamentals. However, Cathay's sharper upward trajectory signals stronger near-term operating momentum.
A8: 2. INVESTING CASH FLOW (CFI)
A9: SIA — Trend | B9: SIA's capex was SGD 1,512mn (FY23) → SGD 1,231mn (FY24) → SGD 1,768mn (FY25). The FY25 jump reflects fresh aircraft orders and continued fleet renewal. A notable outlier in FY25 was SGD 1,006.8mn invested in Air India (Air India–Vistara stake), plus SGD 1,739mn in fixed deposits with maturities over 12 months — inflating total CFI outflow to SGD 3,302mn. Excluding treasury placements and the Air India stake, core capex is more consistent. This is a one-off strategic bet on India's aviation growth.
A10: Cathay — Trend | B10: Cathay is in a sustained heavy-investment cycle: HKD 8,900mn (FY23) → HKD 9,207mn (FY24) → HKD 9,830mn (FY25). This reflects a committed fleet renewal program with 127,700mn HKD in authorised-and-contracted capex commitments outstanding at end FY25. The scale of Cathay's capital commitment significantly exceeds SIA's in both absolute and relative terms — a forward bet on capacity expansion particularly into mainland China and cargo.
A11: Comparison | B11: Both airlines are net investing cash outflow businesses (as expected for capital-intensive aviation). SIA's FY25 outflow (INR ~245,742mn) spikes due to the Air India investment. Cathay's outflow (INR ~90,217mn) is lower on the INR scale but represents a consistently heavy investment rate as a proportion of its revenue. CFO-to-Capex ratios remain comfortable for both: SIA ~2.7x, Cathay ~2.6x in FY25 — both companies are self-funding their capex from operations.
A13: 3. FINANCING CASH FLOW (CFF)
A14: SIA — Trend | B14: SIA's CFF has been consistently negative across the 3 years, reflecting the unwinding of its COVID-era capital structure: massive MCB (Mandatory Convertible Bond) redemptions — SGD 3,180mn (FY23), SGD 5,064mn (FY24), SGD 1,745mn (FY25). These were Temasek-backed instruments raised during COVID. Additionally, rising dividends (SGD 596mn → SGD 1,130mn → SGD 1,429mn) reflect profit recovery and shareholder return. By FY25 the MCB overhang is largely cleared, making FY26 financing flows likely lighter.
A15: Cathay — Trend | B15: Cathay's FY23 CFF was an unusual positive (+HKD 461mn) reflecting fresh debt drawdowns before the COVID recap unwind. FY24 saw a massive CFF outflow (HKD 19,834mn) driven by repayment of the HKD 9,750mn government preference shares (the 2020 bailout) and HKD 7,029mn convertible bond repurchase — effectively a financial clean-up year. FY25 outflow (HKD 15,452mn) is dominated by loan repayments and rising ordinary dividends (HKD 4,491mn), reflecting restored earnings confidence.
A16: Comparison | B16: Both airlines have exited their pandemic financing structures through heavy FY23-FY25 repayments. Cathay's restructuring was more acute (government equity injection vs SIA's MCBs). Going forward, both should see moderating CFF outflows with cleaner balance sheets, though Cathay's ongoing heavy capex pipeline will require sustained refinancing.
A18: 4. KEY RATIOS & OBSERVATIONS
A19: CFO/Capex | B19: SIA: 2.8x (FY23), 4.1x (FY24), 2.7x (FY25) — strong coverage with FY24 elevated by high CFO. Cathay: 2.0x (FY23), 2.6x (FY24), 2.6x (FY25) — improving and stable. Both companies generate sufficient operating cash to fully fund capital expenditure internally, with surplus to service debt and pay dividends.
A20: Cash Balance | B20: SIA's closing cash fell sharply — SGD 5,703mn → SGD 11,256mn → SGD 8,257mn — the FY24 peak followed by drawdown for Air India investment and MCB redemptions. Cathay's closing cash dipped in FY24 (HKD 5,444mn) after the bailout repayments, then recovered to HKD 7,990mn in FY25. Both companies maintain adequate liquidity buffers relative to their annual operating needs.
A21: Overall verdict | B21: Cathay shows stronger cash generation momentum (CFO growing faster, capex coverage stable). SIA shows financial discipline (balance sheet repair complete, rising dividends, strategic investment in Air India as a long-term growth bet). For an investor, Cathay is the higher cash-growth story; SIA is the capital-return + balance-sheet-quality story.
