Workbook

Sheet Group Member Details
C4: Team Members | F4: FT Number
D5: Harshraj | F5: FT272017
D6: Naman | F6: FT272022
D7: Ojasvi | F7: FT261010R
D8: Tanmay | F8: FT272069
D9: Pushkar | F9: FT272056
D10: Tanya | F10: FT272073

Sheet Case 1 - ESOP
A1: Case 1: The Startup ESOP Buyback Decision
A3: Given Data
A4: Option A - cash today | B4: 600000
A5: Option B - expected in 4 years | B5: 950000
A6: Discount rate (r) | B6: 0.09
A7: Time horizon, n (years) | B7: 4
A9: Q1. Future Value of Option A at Year 4
A10: Formula: FV = PV x (1+r)^n
A11: FV of Option A | B11: =FV(B6,B7,0,-B4) -> 846948.97
A12: Interpretation: Option A's future value is less than Option B's stated year value, showing that cash flows at different points in time cannot be compared directly, they must be moved to a common time point first before comparison.
A14: Q2. Present Value of Option B
A15: Formula: PV = FV / (1+r)^n
A16: PV of Option B | B16: =PV(B6,B7,0,-B5) -> 673003.95
A17: Interpretation: Rs 9,50,000, 4 years from now is worth less than Rs 9,50,000 today because money in hand today can be invested at 9% p.a. and grow into more by year 4
A19: Q3. Which Option Should Meera Choose?
A20: Comparison Point | B20: Option A | C20: Option B | D20: Better Choice
A21: At Year 4 (future value) | B21: =B11 -> 846948.97 | C21: =B5 -> 950000 | D21: =IF(B21>C21,"Option A","Option B") -> Option B
A22: At Year 0 (present value) | B22: =B4 -> 600000 | C22: =B16 -> 673003.95 | D22: =IF(B22>C22,"Option A","Option B") -> Option B
A24: Meera should choose: | B24: =D22 -> Option B
A25: Interpretation: As long as the same discount rate is used, comparing at any common time point gives a consistent ranking. However, Option B carries business risk, unlike a risk-free bank FD. Hence, Meera should really apply a higher, risk-adjusted discount rate to Option B rather than the same 9%.

Sheet Case 2 - Education Fund
A1: Case 2: Karan's Child Education Fund
A3: Given Data
A4: Target corpus, FV | B4: 7500000
A5: Time horizon, n (years) | B5: 12
A6: Assumed annual return, r | B6: 0.12
A9: Q1. Corpus from Rs 3,00,000/Year Ordinary Annuity
A10: Proposed annual investment (Q1) | B10: 300000
A11: Formula: FV = PV x [((1+r)^n - 1) / r]
A12: Accumulated corpus | B12: =FV(B6,B5,-B10,0,0) -> 7239940
A13: Shortfall of - | B13: =B4-B12 -> 260060.02
A14: Interpretation: The shortfall above tells Karan will not be able to meet his corpus target with Rs. 3 Lakh/year
A16: Q2. Fixed Annual Contribution Needed
A17: Formula: | B17: =_xlfn.FORMULATEXT(B18) -> =-PMT(B6,B5,0,B4,0)
A18: Required annual investment | B18: =-PMT(B6,B5,0,B4,0) -> 310776.06
A20: Q3. Fixed Annual Contribution - Annuity Due
A21: Formula: PMT = FV / {[((1+r)^n - 1)/r] x (1+r)}
A22: Required annual investment (year-start) | B22: =-PMT(B6,B5,0,B4,1) -> 277478.62
A23: Annual saving vs. ordinary annuity | B23: =B18-B22 -> 33297.435
A24: Interpretation: Paying at the start of the year gives each contribution 1 extra period of compounding, so a smaller annual amount reaches the same target.
A26: Q4. Monthly SIP (12% p.a. Compounded Monthly, 144 Months)
A27: Nominal annual rate | B27: 0.12
A28: Monthly rate, m = nominal/12 | B28: =B27/12 -> 0.01
A29: Number of months, n | B29: 144
A30: Required monthly SIP | B30: =-PMT(B28,B29,0,B4,0) -> 23506.436
A32: Effective Annual Rate (EAR) implied by 12% compounded monthly | B32: =(1+B28)^12-1 -> 0.12682503
A33: Interpretation: The EAR is higher than the quoted nominal 12% because monthly compounding lets interest earned early in the year start earning interest itself. This is why SIP returns actually earned can exceed the quoted nominal rate.

Sheet Case 3 - Home Loan
A1: Case 3: The Home Loan Prepayment Decision
A3: Given Data
A4: Loan principal, P | B4: 3500000
A5: Annual interest rate | B5: 0.09
A6: Monthly rate, m = annual/12 | B6: =B5/12 -> 0.0075
A7: Tenure Option 1 (months) | B7: 144
A8: Tenure Option 2 (months) | B8: 96
A10: Q1. Monthly EMI - 12-Year (144-Month) Loan
A11: Formula: EMI = P x m x (1+m)^n / [(1+m)^n - 1]
A12: EMI (144 months) | B12: =-PMT(B6,B7,B4,0,0) -> 39831.074
A14: Q2. Amortization Schedule - 12-Year Loan
A15: Full 144-month schedule is in the - Amortization Schedule tab. Glimpse for the same is given below -
A17: Year | B17: Opening Balance | C17: Total EMI Paid | D17: Interest Portion | E17: Principal Portion | F17: Closing Balance
A18: 1 | B18: =B4 -> 3500000 | C18: =SUM('Amortization Schedule'!C4:C15) -> 477972.89 | D18: =SUM('Amortization Schedule'!D4:D15) -> 308106.43 | E18: =SUM('Amortization Schedule'!E4:E15) -> 169866.46 | F18: ='Amortization Schedule'!G15 -> 3330133.5
A19: 2 | B19: ='Amortization Schedule'!G15 -> 3330133.5 | C19: =SUM('Amortization Schedule'!C16:C27) -> 477972.89 | D19: =SUM('Amortization Schedule'!D16:D27) -> 292171.79 | E19: =SUM('Amortization Schedule'!E16:E27) -> 185801.11 | F19: ='Amortization Schedule'!G27 -> 3144332.4
A20: 3 | B20: ='Amortization Schedule'!G27 -> 3144332.4 | C20: =SUM('Amortization Schedule'!C28:C39) -> 477972.89 | D20: =SUM('Amortization Schedule'!D28:D39) -> 274742.36 | E20: =SUM('Amortization Schedule'!E28:E39) -> 203230.53 | F20: ='Amortization Schedule'!G39 -> 2941101.9
A21: 4 | B21: ='Amortization Schedule'!G39 -> 2941101.9 | C21: =SUM('Amortization Schedule'!C40:C51) -> 477972.89 | D21: =SUM('Amortization Schedule'!D40:D51) -> 255677.94 | E21: =SUM('Amortization Schedule'!E40:E51) -> 222294.96 | F21: ='Amortization Schedule'!G51 -> 2718806.9
A22: 5 | B22: ='Amortization Schedule'!G51 -> 2718806.9 | C22: =SUM('Amortization Schedule'!C52:C63) -> 477972.89 | D22: =SUM('Amortization Schedule'!D52:D63) -> 234825.13 | E22: =SUM('Amortization Schedule'!E52:E63) -> 243147.76 | F22: ='Amortization Schedule'!G63 -> 2475659.2
A23: 6 | B23: ='Amortization Schedule'!G63 -> 2475659.2 | C23: =SUM('Amortization Schedule'!C64:C75) -> 477972.89 | D23: =SUM('Amortization Schedule'!D64:D75) -> 212016.2 | E23: =SUM('Amortization Schedule'!E64:E75) -> 265956.69 | F23: ='Amortization Schedule'!G75 -> 2209702.5
A24: 7 | B24: ='Amortization Schedule'!G75 -> 2209702.5 | C24: =SUM('Amortization Schedule'!C76:C87) -> 477972.89 | D24: =SUM('Amortization Schedule'!D76:D87) -> 187067.63 | E24: =SUM('Amortization Schedule'!E76:E87) -> 290905.27 | F24: ='Amortization Schedule'!G87 -> 1918797.2
A25: 8 | B25: ='Amortization Schedule'!G87 -> 1918797.2 | C25: =SUM('Amortization Schedule'!C88:C99) -> 477972.89 | D25: =SUM('Amortization Schedule'!D88:D99) -> 159778.7 | E25: =SUM('Amortization Schedule'!E88:E99) -> 318194.19 | F25: ='Amortization Schedule'!G99 -> 1600603
A26: 9 | B26: ='Amortization Schedule'!G99 -> 1600603 | C26: =SUM('Amortization Schedule'!C100:C111) -> 477972.89 | D26: =SUM('Amortization Schedule'!D100:D111) -> 129929.9 | E26: =SUM('Amortization Schedule'!E100:E111) -> 348043 | F26: ='Amortization Schedule'!G111 -> 1252560
A27: 10 | B27: ='Amortization Schedule'!G111 -> 1252560 | C27: =SUM('Amortization Schedule'!C112:C123) -> 477972.89 | D27: =SUM('Amortization Schedule'!D112:D123) -> 97281.062 | E27: =SUM('Amortization Schedule'!E112:E123) -> 380691.83 | F27: ='Amortization Schedule'!G123 -> 871868.21
A28: 11 | B28: ='Amortization Schedule'!G123 -> 871868.21 | C28: =SUM('Amortization Schedule'!C124:C135) -> 477972.89 | D28: =SUM('Amortization Schedule'!D124:D135) -> 61569.542 | E28: =SUM('Amortization Schedule'!E124:E135) -> 416403.35 | F28: ='Amortization Schedule'!G135 -> 455464.86
A29: 12 | B29: ='Amortization Schedule'!G135 -> 455464.86 | C29: =SUM('Amortization Schedule'!C136:C147) -> 477972.89 | D29: =SUM('Amortization Schedule'!D136:D147) -> 22508.035 | E29: =SUM('Amortization Schedule'!E136:E147) -> 455464.86 | F29: ='Amortization Schedule'!G147 -> 3.2960088e-09
A31: Q3. Total Interest Paid - 12 -Year Tenure
A32: Formula: Total Interest = (EMI x n) - P
A33: Total interest over 12 years | B33: =(B12*B7)-B4 -> 2235674.7
A35: Q4. EMI and Total Interest - 8 -Year (96-Month) Tenure
A36: EMI (96 months) | B36: =-PMT(B6,B8,B4,0,0) -> 51275.711
A37: Total interest (96 months) | B37: =(B36*B8)-B4 -> 1422468.3
A38: EMI increase vs. 12-yr loan | B38: =B36-B12 -> 11444.637
A39: Interest saved vs. 12-yr loan | B39: =B33-B37 -> 813206.41
A40: Interpretation: The 8 year tenure raises the EMI but cuts total interest paid, the trade-off between monthly affordability and total cost of borrowing.
A42: Q5. Outstanding Balance After 48 EMIs (End of Year 4, 12-Year Loan)
A43: Outstanding balance before prepayment | B43: ='Amortization Schedule'!G51 -> 2718806.9
A45: Q6. Applying the Rs 4,00,000 Prepayment
A46: Prepayment amount | B46: 400000
A47: New outstanding balance after prepayment | B47: =B43-B46 -> 2318806.9
A48: Remaining original tenure at this point (months) | B48: =B7-48 -> 96
...

Sheet Amortization Schedule
A1: Case 3 - Full Amortization Schedule (144 Months)
A3: Month | B3: Opening Balance | C3: EMI | D3: Interest | E3: Principal | G3: Closing Balance
A4: 1 | B4: ='Case 3 - Home Loan'!$B$4 -> 3500000 | C4: ='Case 3 - Home Loan'!$B$12 -> 39831.074 | D4: =B4*'Case 3 - Home Loan'!$B$6 -> 26250 | E4: =C4-D4 -> 13581.074 | G4: =B4-E4 -> 3486418.9
A5: 2 | B5: =G4 -> 3486418.9 | C5: ='Case 3 - Home Loan'!$B$12 -> 39831.074 | D5: =B5*'Case 3 - Home Loan'!$B$6 -> 26148.142 | E5: =C5-D5 -> 13682.932 | G5: =B5-E5 -> 3472736
A6: 3 | B6: =G5 -> 3472736 | C6: ='Case 3 - Home Loan'!$B$12 -> 39831.074 | D6: =B6*'Case 3 - Home Loan'!$B$6 -> 26045.52 | E6: =C6-D6 -> 13785.554 | G6: =B6-E6 -> 3458950.4
A7: 4 | B7: =G6 -> 3458950.4 | C7: ='Case 3 - Home Loan'!$B$12 -> 39831.074 | D7: =B7*'Case 3 - Home Loan'!$B$6 -> 25942.128 | E7: =C7-D7 -> 13888.946 | G7: =B7-E7 -> 3445061.5
A8: 5 | B8: =G7 -> 3445061.5 | C8: ='Case 3 - Home Loan'!$B$12 -> 39831.074 | D8: =B8*'Case 3 - Home Loan'!$B$6 -> 25837.961 | E8: =C8-D8 -> 13993.113 | G8: =B8-E8 -> 3431068.4
A9: 6 | B9: =G8 -> 3431068.4 | C9: ='Case 3 - Home Loan'!$B$12 -> 39831.074 | D9: =B9*'Case 3 - Home Loan'!$B$6 -> 25733.013 | E9: =C9-D9 -> 14098.062 | G9: =B9-E9 -> 3416970.3
A10: 7 | B10: =G9 -> 3416970.3 | C10: ='Case 3 - Home Loan'!$B$12 -> 39831.074 | D10: =B10*'Case 3 - Home Loan'!$B$6 -> 25627.277 | E10: =C10-D10 -> 14203.797 | G10: =B10-E10 -> 3402766.5
A11: 8 | B11: =G10 -> 3402766.5 | C11: ='Case 3 - Home Loan'!$B$12 -> 39831.074 | D11: =B11*'Case 3 - Home Loan'!$B$6 -> 25520.749 | E11: =C11-D11 -> 14310.325 | G11: =B11-E11 -> 3388456.2
A12: 9 | B12: =G11 -> 3388456.2 | C12: ='Case 3 - Home Loan'!$B$12 -> 39831.074 | D12: =B12*'Case 3 - Home Loan'!$B$6 -> 25413.421 | E12: =C12-D12 -> 14417.653 | G12: =B12-E12 -> 3374038.5
A13: 10 | B13: =G12 -> 3374038.5 | C13: ='Case 3 - Home Loan'!$B$12 -> 39831.074 | D13: =B13*'Case 3 - Home Loan'!$B$6 -> 25305.289 | E13: =C13-D13 -> 14525.785 | G13: =B13-E13 -> 3359512.8
A14: 11 | B14: =G13 -> 3359512.8 | C14: ='Case 3 - Home Loan'!$B$12 -> 39831.074 | D14: =B14*'Case 3 - Home Loan'!$B$6 -> 25196.346 | E14: =C14-D14 -> 14634.729 | G14: =B14-E14 -> 3344878
A15: 12 | B15: =G14 -> 3344878 | C15: ='Case 3 - Home Loan'!$B$12 -> 39831.074 | D15: =B15*'Case 3 - Home Loan'!$B$6 -> 25086.585 | E15: =C15-D15 -> 14744.489 | G15: =B15-E15 -> 3330133.5
A16: 13 | B16: =G15 -> 3330133.5 | C16: ='Case 3 - Home Loan'!$B$12 -> 39831.074 | D16: =B16*'Case 3 - Home Loan'!$B$6 -> 24976.002 | E16: =C16-D16 -> 14855.073 | G16: =B16-E16 -> 3315278.5
... A147: 144 | B147: =G146 -> 39534.565 | C147: ='Case 3 - Home Loan'!$B$12 -> 39831.074 | D147: =B147*'Case 3 - Home Loan'!$B$6 -> 296.50924 | E147: =C147-D147 -> 39534.565 | G147: =B147-E147 -> 3.2960088e-09

Sheet Scenario - LumpSum vs SIP
A1: Case: Priya's Diwali Bonus - Lump Sum vs. SIP Investment Background Priya receives a Diwali bonus of ₹6,00,000. She wants to invest it for 10 years in an equity mutual fund. She is unsure whether to invest the entire bonus immediately as a lump sum, or to keep it in a savings account and drip-feed it into the fund via a 12-month SIP before letting it grow untouched for the rest of the horizon. When she first ran the numbers, Priya assumed the fund would earn 14% p.a. But equity returns are never guaranteed. Her financial advisor suggests she also check how the decision holds up if the market does much better than expected (an optimistic scenario) or much worse (a pessimistic scenario), so she isn't caught off guard either way. Data Given • Bonus amount = ₹6,00,000 • Total investment horizon = 10 years • Option A (Lump Sum): invest the full ₹6,00,000 today; let it grow annually for all 10 years • Option B (Delayed via SIP): invest ₹50,000 at the end of every month for the first 12 months (an ordinary annuity, monthly compounding), this uses up the full ₹6,00,000 bonus by the end of year 1. The corpus built by the end of year 1 then grows annually for the remaining 9 years Return Scenarios The same two investment options (A and B) must be evaluated under each of the three return assumptions below. The monthly compounding rate used for the 12-month SIP build-up is simply the annual rate divided by 12, consistent with each scenario. Scenario - Assumed Annual Return - Rationale Base - 14% p.a. - Priya's original, "most likely" planning assumption for a diversified equity fund Optimistic - 18% p.a. - Strong bull market / favourable economic growth over the decade Pessimistic - 9% p.a. - Weak market conditions, a couple of recession years, or a more conservative fund mix Questions Q1. For each of the three scenarios (Base, Optimistic, Pessimistic), compute the future value of Option A, the lump sum of ₹6,00,000 invested today and grown for the full 10 years at that scenario's rate. Q2. For each of the three scenarios, compute the corpus Priya accumulates by the end of Year 1 under Option B, from investing ₹50,000 at the end of every month for 12 months at that scenario's monthly rate. Q3. For each scenario, grow the Year-1 corpus from Q2 at that scenario's annual rate for the remaining 9 years to find Priya's total corpus at the end of year 10 under Option B. Q4. For each scenario, compute the "cost of delay", the gap between Option A's and Option B's final corpus (FV of Option A minus FV of Option B), both in absolute rupees and as a percentage of Option A's corpus. Q5. Across all three scenarios, does Option A (Lump Sum) ever stop being the better choice? What does this tell Priya about how much the choice between lump sum and SIP investing actually depends on her return assumption, versus depending on something else entirely?
A7: Priya's Diwali Bonus - Lump Sum vs. SIP (Base / Optimistic / Pessimistic)
A9: Given Data (common to all scenarios)
A10: Bonus amount | B10: 600000
A11: Total investment horizon (years) | B11: 10
A12: Option B: monthly SIP amount | B12: 50000
A13: Option B: SIP duration (months) | B13: 12
A15: Return Scenarios
A16: Scenario | B16: Annual Return, r | C16: Monthly Rate, m = r/12
A17: Base | B17: 0.14 | C17: =B17/12 -> 0.011666667
A18: Optimistic | B18: 0.18 | C18: =B18/12 -> 0.015
A19: Pessimistic | B19: 0.09 | C19: =B19/12 -> 0.0075
A21: Q1. Future Value of Option A (Lump Sum) - Each Scenario
A22: Formula: FV = PV x (1+r)^n
A23: Scenario | B23: FV of Option A (Year 10)
A24: Base | B24: =FV(B17,$B$11,0,-$B$10) -> 2224332.8
A25: Optimistic | B25: =FV(B18,$B$11,0,-$B$10) -> 3140301.3
A26: Pessimistic | B26: =FV(B19,$B$11,0,-$B$10) -> 1420418.2
A28: Q2. Corpus at End of Year 1 (Option B, SIP) - Each Scenario
A29: Formula: FV = PMT x [((1+m)^n - 1) / m] (month-end)
A30: Scenario | B30: Corpus at End of Year 1
A31: Base | B31: =FV(C17,$B$13,-$B$12,0,0) -> 640037.27
A32: Optimistic | B32: =FV(C18,$B$13,-$B$12,0,0) -> 652060.57
A33: Pessimistic | B33: =FV(C19,$B$13,-$B$12,0,0) -> 625379.32
A35: Q3. Future Value of Option B at Year 10 - Each Scenario
A36: Formula: grow the Year-1 corpus at r for the remaining (n-1) years
A37: Scenario | B37: FV of Option B (Year 10)
A38: Base | B38: =FV(B17,$B$11-1,0,-B31) -> 2081368.2
A39: Optimistic | B39: =FV(B18,$B$11-1,0,-B32) -> 2892184.6
A40: Pessimistic | B40: =FV(B19,$B$11-1,0,-B33) -> 1358257.1
A42: Q4. Cost of Delay - Each Scenario
A43: Scenario | B43: FV Option A | C43: FV Option B | D43: Cost of Delay (Rs) | E43: Cost of Delay (%)
A44: Base | B44: =B24 -> 2224332.8 | C44: =B38 -> 2081368.2 | D44: =B44-C44 -> 142964.54 | E44: =D44/B44 -> 0.064273
A45: Optimistic | B45: =B25 -> 3140301.3 | C45: =B39 -> 2892184.6 | D45: =B45-C45 -> 248116.75 | E45: =D45/B45 -> 0.079010492
A46: Pessimistic | B46: =B26 -> 1420418.2 | C46: =B40 -> 1358257.1 | D46: =B46-C46 -> 62161.067 | E46: =D46/B46 -> 0.043762511
A48: Interpretation: The absolute rupee cost of delay rises as the assumed return rises (highest in the Optimistic scenario, lowest in the Pessimistic scenario) - because a higher return rate makes every year of "lost" compounding more valuable. Timing therefore matters more in strong markets and less in weak ones, even though the percentage cost stays in a fairly narrow band across scenarios.
A50: Q5. Does Option A Ever Stop Being the Better Choice?
A51: Better option, Base | B51: =IF(B44>C44,"Option A (Lump Sum)","Option B (SIP)") -> Option A (Lump Sum)
A52: Better option, Optimistic | B52: =IF(B45>C45,"Option A (Lump Sum)","Option B (SIP)") -> Option A (Lump Sum)
A53: Better option, Pessimistic | B53: =IF(B46>C46,"Option A (Lump Sum)","Option B (SIP)") -> Option A (Lump Sum)
...
