Workbook

Sheet APP
A1: Aggregate Production Plan (Hybrid Strategy) - Skoda Kushaq
A3: Parameters
A4: Regular-time production (RP, units/month) | B4: 1350
A5: Overtime cap (OT_MAX, units/month) | B5: 250
A6: Subcontract cap (SC_MAX, units/month) | B6: 300
A7: Regular-time cost (Rs/unit) | B7: 700000
A8: Overtime cost (Rs/unit) | B8: 750000
A9: Subcontract cost (Rs/unit) | B9: 780000
A10: Holding cost (Rs/unit/month) | B10: 5000
A11: Backorder cost (Rs/unit/month) | B11: 15000
A13: Month-by-month plan
A14: Month | B14: Demand | C14: Beg. Inv/(Backlog) | D14: Regular Prod (RP) | E14: Overtime (OT) | F14: Subcontract (SC) | G14: Total Supply | H14: End Inv/(Backlog)
A15: 1 | B15: 1000 | C15: 0 | D15: =$B$4 -> 1350 | E15: =MIN($B$5, MAX(0, B15-(C15+D15))) -> 0 | F15: =MIN($B$6, MAX(0, B15-(C15+D15+E15))) -> 0 | G15: =D15+E15+F15 -> 1350 | H15: =C15+G15-B15 -> 350
A16: 2 | B16: 1100 | C16: =H15 -> 350 | D16: =$B$4 -> 1350 | E16: =MIN($B$5, MAX(0, B16-(C16+D16))) -> 0 | F16: =MIN($B$6, MAX(0, B16-(C16+D16+E16))) -> 0 | G16: =D16+E16+F16 -> 1350 | H16: =C16+G16-B16 -> 600
A17: 3 | B17: 1300 | C17: =H16 -> 600 | D17: =$B$4 -> 1350 | E17: =MIN($B$5, MAX(0, B17-(C17+D17))) -> 0 | F17: =MIN($B$6, MAX(0, B17-(C17+D17+E17))) -> 0 | G17: =D17+E17+F17 -> 1350 | H17: =C17+G17-B17 -> 650
A18: 4 | B18: 1700 | C18: =H17 -> 650 | D18: =$B$4 -> 1350 | E18: =MIN($B$5, MAX(0, B18-(C18+D18))) -> 0 | F18: =MIN($B$6, MAX(0, B18-(C18+D18+E18))) -> 0 | G18: =D18+E18+F18 -> 1350 | H18: =C18+G18-B18 -> 300
A19: 5 | B19: 2100 | C19: =H18 -> 300 | D19: =$B$4 -> 1350 | E19: =MIN($B$5, MAX(0, B19-(C19+D19))) -> 250 | F19: =MIN($B$6, MAX(0, B19-(C19+D19+E19))) -> 200 | G19: =D19+E19+F19 -> 1800 | H19: =C19+G19-B19 -> 0
A20: 6 | B20: 2200 | C20: =H19 -> 0 | D20: =$B$4 -> 1350 | E20: =MIN($B$5, MAX(0, B20-(C20+D20))) -> 250 | F20: =MIN($B$6, MAX(0, B20-(C20+D20+E20))) -> 300 | G20: =D20+E20+F20 -> 1900 | H20: =C20+G20-B20 -> -300
A21: 7 | B21: 1800 | C21: =H20 -> -300 | D21: =$B$4 -> 1350 | E21: =MIN($B$5, MAX(0, B21-(C21+D21))) -> 250 | F21: =MIN($B$6, MAX(0, B21-(C21+D21+E21))) -> 300 | G21: =D21+E21+F21 -> 1900 | H21: =C21+G21-B21 -> -200
A22: 8 | B22: 1300 | C22: =H21 -> -200 | D22: =$B$4 -> 1350 | E22: =MIN($B$5, MAX(0, B22-(C22+D22))) -> 150 | F22: =MIN($B$6, MAX(0, B22-(C22+D22+E22))) -> 0 | G22: =D22+E22+F22 -> 1500 | H22: =C22+G22-B22 -> 0
A25: Cost Breakdown
A26: Cost component | B26: Rate | C26: Quantity (formula) | D26: Cost (Rs)
A27: Regular time | B27: =$B$7 -> 700000 | C27: =SUM(D15:D22) -> 10800 | D27: =B27*C27 -> 7560000000
A28: Overtime | B28: =$B$8 -> 750000 | C28: =SUM(E15:E22) -> 900 | D28: =B28*C28 -> 675000000
A29: Subcontract | B29: =$B$9 -> 780000 | C29: =SUM(F15:F22) -> 800 | D29: =B29*C29 -> 624000000
A30: Inventory holding | B30: =$B$10 -> 5000 | C30: =SUMIF(H15:H22,">0") -> 1900 | D30: =B30*C30 -> 9500000
A31: Backorder | B31: =$B$11 -> 15000 | C31: =-SUMIF(H15:H22,"<0") -> 500 | D31: =B31*C31 -> 7500000
A32: TOTAL APP COST (Rs) | D32: =SUM(D27:D31) -> 8876000000

Sheet BOM
A1: Bill of Materials - Skoda Kushaq
A3: Item | B3: Level | C3: Parent | D3: Qty/Parent | E3: Lot rule | F3: Lot size | G3: Lead time (mo.) | H3: On-hand inv.
A4: Skoda Kushaq (finished vehicle) | B4: 0 | C4: — | D4: 1 | E4: L4L | F4: — | G4: 1 | H4: 15
A5: Engine Assembly | B5: 1 | C5: Kushaq | D5: 1 | E5: L4L | F5: — | G5: 1 | H5: 0
A6: Chassis Assembly | B6: 1 | C6: Kushaq | D6: 1 | E6: L4L | F6: — | G6: 1 | H6: 0
A7: Body Assembly | B7: 1 | C7: Kushaq | D7: 1 | E7: L4L | F7: — | G7: 1 | H7: 0
A8: Engine Block | B8: 2 | C8: Engine Assembly | D8: 1 | E8: FOQ | F8: 2000 | G8: 2 | H8: 1000
A9: Wiring Harness | B9: 2 | C9: Engine Assembly | D9: 1 | E9: L4L | F9: — | G9: 1 | H9: 0
A10: Fastener Kit | B10: 2 | C10: Engine Asm.(x2)/Chassis Asm.(x3) | D10: 2 / 3 | E10: FOQ | F10: 8000 | G10: 1 | H10: 6000
A11: Wheel & Tyre Sub-assembly | B11: 2 | C11: Chassis Assembly | D11: 4 | E11: L4L | F11: — | G11: 1 | H11: 0
A12: Steel Body Panel Set | B12: 2 | C12: Body Assembly | D12: 1 | E12: FOQ | F12: 2000 | G12: 2 | H12: 1000
A13: Paint (litres) | B13: 2 | C13: Body Assembly | D13: 3 | E13: FOQ | F13: 5000 | G13: 1 | H13: 0
A14: Tyre | B14: 3 | C14: Wheel & Tyre Sub-asm. | D14: 1 | E14: FOQ | F14: 6000 | G14: 2 | H14: 0
A15: Alloy Rim | B15: 3 | C15: Wheel & Tyre Sub-asm. | D15: 1 | E15: L4L | F15: — | G15: 1 | H15: 0

Sheet MRP
A1: Material Requirements Planning - Skoda Kushaq (all items, Months 1 - 8)
C2: Period | D2: M1 | E2: M2 | F2: M3 | G2: M4 | H2: M5 | I2: M6 | J2: M7 | K2: M8
A4: Item: | B4: Skoda Kushaq (finished vehicle)
A5: OH: | B5: 15
A6: LT (mo): | B6: 1
A7: Lot rule: | B7: L4L
C8: Gross Requirements | D8: =APP!G15 -> 1350 | E8: =APP!G16 -> 1350 | F8: =APP!G17 -> 1350 | G8: =APP!G18 -> 1350 | H8: =APP!G19 -> 1800 | I8: =APP!G20 -> 1900 | J8: =APP!G21 -> 1900 | K8: =APP!G22 -> 1500
C9: Projected Avail. Balance | D9: =$B$5+D11-D8 -> 0 | E9: =D9+E11-E8 -> 0 | F9: =E9+F11-F8 -> 0 | G9: =F9+G11-G8 -> 0 | H9: =G9+H11-H8 -> 0 | I9: =H9+I11-I8 -> 0 | J9: =I9+J11-J8 -> 0 | K9: =J9+K11-K8 -> 0
C10: Net Requirements | D10: =MAX(0,D8-$B$5) -> 1335 | E10: =MAX(0,E8-D9) -> 1350 | F10: =MAX(0,F8-E9) -> 1350 | G10: =MAX(0,G8-F9) -> 1350 | H10: =MAX(0,H8-G9) -> 1800 | I10: =MAX(0,I8-H9) -> 1900 | J10: =MAX(0,J8-I9) -> 1900 | K10: =MAX(0,K8-J9) -> 1500
C11: Planned Order Receipts | D11: =D10 -> 1335 | E11: =E10 -> 1350 | F11: =F10 -> 1350 | G11: =G10 -> 1350 | H11: =H10 -> 1800 | I11: =I10 -> 1900 | J11: =J10 -> 1900 | K11: =K10 -> 1500
C12: Planned Order Releases | D12: =D11+E11 -> 2685 | E12: =F11 -> 1350 | F12: =G11 -> 1350 | G12: =H11 -> 1800 | H12: =I11 -> 1900 | I12: =J11 -> 1900 | J12: =K11 -> 1500 | K12: =0 -> 0
A14: Item: | B14: Engine Assembly
A15: OH: | B15: 0
A16: LT (mo): | B16: 1
A17: Lot rule: | B17: L4L
C18: Gross Requirements | D18: =D12*1 -> 2685 | E18: =E12*1 -> 1350 | F18: =F12*1 -> 1350 | G18: =G12*1 -> 1800 | H18: =H12*1 -> 1900 | I18: =I12*1 -> 1900 | J18: =J12*1 -> 1500 | K18: =K12*1 -> 0
C19: Projected Avail. Balance | D19: =$B$15+D21-D18 -> 0 | E19: =D19+E21-E18 -> 0 | F19: =E19+F21-F18 -> 0 | G19: =F19+G21-G18 -> 0 | H19: =G19+H21-H18 -> 0 | I19: =H19+I21-I18 -> 0 | J19: =I19+J21-J18 -> 0 | K19: =J19+K21-K18 -> 0
C20: Net Requirements | D20: =MAX(0,D18-$B$15) -> 2685 | E20: =MAX(0,E18-D19) -> 1350 | F20: =MAX(0,F18-E19) -> 1350 | G20: =MAX(0,G18-F19) -> 1800 | H20: =MAX(0,H18-G19) -> 1900 | I20: =MAX(0,I18-H19) -> 1900 | J20: =MAX(0,J18-I19) -> 1500 | K20: =MAX(0,K18-J19) -> 0
C21: Planned Order Receipts | D21: =D20 -> 2685 | E21: =E20 -> 1350 | F21: =F20 -> 1350 | G21: =G20 -> 1800 | H21: =H20 -> 1900 | I21: =I20 -> 1900 | J21: =J20 -> 1500 | K21: =K20 -> 0
C22: Planned Order Releases | D22: =D21+E21 -> 4035 | E22: =F21 -> 1350 | F22: =G21 -> 1800 | G22: =H21 -> 1900 | H22: =I21 -> 1900 | I22: =J21 -> 1500 | J22: =K21 -> 0 | K22: =0 -> 0
A24: Item: | B24: Chassis Assembly
A25: OH: | B25: 0
A26: LT (mo): | B26: 1
A27: Lot rule: | B27: L4L
C28: Gross Requirements | D28: =D12*1 -> 2685 | E28: =E12*1 -> 1350 | F28: =F12*1 -> 1350 | G28: =G12*1 -> 1800 | H28: =H12*1 -> 1900 | I28: =I12*1 -> 1900 | J28: =J12*1 -> 1500 | K28: =K12*1 -> 0
C29: Projected Avail. Balance | D29: =$B$25+D31-D28 -> 0 | E29: =D29+E31-E28 -> 0 | F29: =E29+F31-F28 -> 0 | G29: =F29+G31-G28 -> 0 | H29: =G29+H31-H28 -> 0 | I29: =H29+I31-I28 -> 0 | J29: =I29+J31-J28 -> 0 | K29: =J29+K31-K28 -> 0
C30: Net Requirements | D30: =MAX(0,D28-$B$25) -> 2685 | E30: =MAX(0,E28-D29) -> 1350 | F30: =MAX(0,F28-E29) -> 1350 | G30: =MAX(0,G28-F29) -> 1800 | H30: =MAX(0,H28-G29) -> 1900 | I30: =MAX(0,I28-H29) -> 1900 | J30: =MAX(0,J28-I29) -> 1500 | K30: =MAX(0,K28-J29) -> 0
C31: Planned Order Receipts | D31: =D30 -> 2685 | E31: =E30 -> 1350 | F31: =F30 -> 1350 | G31: =G30 -> 1800 | H31: =H30 -> 1900 | I31: =I30 -> 1900 | J31: =J30 -> 1500 | K31: =K30 -> 0
C32: Planned Order Releases | D32: =D31+E31 -> 4035 | E32: =F31 -> 1350 | F32: =G31 -> 1800 | G32: =H31 -> 1900 | H32: =I31 -> 1900 | I32: =J31 -> 1500 | J32: =K31 -> 0 | K32: =0 -> 0
A34: Item: | B34: Body Assembly
A35: OH: | B35: 0
A36: LT (mo): | B36: 1
A37: Lot rule: | B37: L4L
C38: Gross Requirements | D38: =D12*1 -> 2685 | E38: =E12*1 -> 1350 | F38: =F12*1 -> 1350 | G38: =G12*1 -> 1800 | H38: =H12*1 -> 1900 | I38: =I12*1 -> 1900 | J38: =J12*1 -> 1500 | K38: =K12*1 -> 0
C39: Projected Avail. Balance | D39: =$B$35+D41-D38 -> 0 | E39: =D39+E41-E38 -> 0 | F39: =E39+F41-F38 -> 0 | G39: =F39+G41-G38 -> 0 | H39: =G39+H41-H38 -> 0 | I39: =H39+I41-I38 -> 0 | J39: =I39+J41-J38 -> 0 | K39: =J39+K41-K38 -> 0
C40: Net Requirements | D40: =MAX(0,D38-$B$35) -> 2685 | E40: =MAX(0,E38-D39) -> 1350 | F40: =MAX(0,F38-E39) -> 1350 | G40: =MAX(0,G38-F39) -> 1800 | H40: =MAX(0,H38-G39) -> 1900 | I40: =MAX(0,I38-H39) -> 1900 | J40: =MAX(0,J38-I39) -> 1500 | K40: =MAX(0,K38-J39) -> 0
C41: Planned Order Receipts | D41: =D40 -> 2685 | E41: =E40 -> 1350 | F41: =F40 -> 1350 | G41: =G40 -> 1800 | H41: =H40 -> 1900 | I41: =I40 -> 1900 | J41: =J40 -> 1500 | K41: =K40 -> 0
C42: Planned Order Releases | D42: =D41+E41 -> 4035 | E42: =F41 -> 1350 | F42: =G41 -> 1800 | G42: =H41 -> 1900 | H42: =I41 -> 1900 | I42: =J41 -> 1500 | J42: =K41 -> 0 | K42: =0 -> 0
A44: Item: | B44: Engine Block
A45: OH: | B45: 1000
...

Sheet Inventory Policy - Tyre
A1: Continuous Review (Q-Model) Inventory Policy - Tyre
A3: Inputs (assumptions)
A4: Mean monthly demand, D̄ (tyres/month) | B4: 6600
A5: Std. dev. of monthly demand, σ (tyres/month) | B5: 900
A6: Supplier lead time, LT (months) | B6: 2
A7: Ordering/setup cost, S (Rs/order) | B7: 30000
A8: Holding cost, H (Rs/tyre/month) | B8: 60
A9: Cycle service level (Z-value) | B9: 1.645
A12: Formulas and results
A13: Economic Order Quantity, Q* = √(2 × D̄ × S / H) | B13: =SQRT(2*$B$4*$B$7/$B$8) -> 2569.0465
A14: Std. dev. of demand during lead time, σ_LT = σ × √LT | B14: =$B$5*SQRT($B$6) -> 1272.7922
A15: Safety Stock, SS = Z × σ_LT | B15: =$B$9*B14 -> 2093.7432
A16: Reorder Point, ROP = (D̄ × LT) + SS | B16: =($B$4*$B$6)+B15 -> 15293.743
A17: Orders per year = (D̄ × 12) / Q* | B17: =($B$4*12)/B13 -> 30.828558
A18: Cycle length (days) = 365 / Orders per year | B18: =365/B17 -> 11.839671
A21: Resulting Policy Summary
A22: Parameter | B22: Value
A23: Order quantity (Q*, EOQ, rounded) | B23: =MROUND(B13,10) -> 2570
A24: Safety stock (SS, rounded) | B24: =MROUND(B15,10) -> 2090
A25: Reorder point (ROP, rounded) | B25: =MROUND(B16,10) -> 15290
A26: Approx. orders per year | B26: =B17 -> 30.828558
A27: Approx. cycle length (days) | B27: =B18 -> 11.839671
